Workbook

Sheet Summary
A2: AS per IT Team
A3: Count of Mapped | B3: Column Labels
A4: Row Labels | B4: No | C4: Yes | D4: Grand Total
A5: Desktop | B5: 33 | C5: 236 | D5: 269
A6: Laptop | B6: 43 | C6: 567 | D6: 610
A7: Server | B7: 8 | C7: 1 | D7: 9
A8: Grand Total | B8: 84 | C8: 804 | D8: 888
B15: 1000
B16: 2000
B17: 3000
B18: 4000
B19: 5000
B20: 6000
B21: 7000
B22: 8000

Sheet Sheet2
A1: Mapped | B1: (All)
A3: Row Labels | B3: Count of Sap Code | C3: Count of Serial numbers | D3: Completion
A4: Desktop | B4: 189 | C4: 189 | D4: =B4/C4 -> 1
A5: Desktop | B5: 2 | C5: 2 | D5: =B5/C5 -> 1
A6: DESKTOP SCADAR | B6: 2 | C6: 2 | D6: =B6/C6 -> 1
A7: Laptop | B7: 609 | C7: 609 | D7: =B7/C7 -> 1
A8: Machine Laptop | B8: 1 | C8: 1 | D8: =B8/C8 -> 1
A9: SCARDA Desktop | B9: 2 | C9: 2 | D9: =B9/C9 -> 1
A10: Server | B10: 9 | C10: 9 | D10: =B10/C10 -> 1
A11: Shared Desktop | B11: 74 | C11: 74 | D11: =B11/C11 -> 1
A12: Grand Total | B12: 888 | C12: 888 | D12: =B12/C12 -> 1

Sheet Sheet3
A3: Row Labels | B3: Count of Serial numbers | C3: Count of Sap Code
A4: Desktop | B4: 189 | C4: 189
A5: 1000 | B5: 6 | C5: 6
A6: 2000 | B6: 92 | C6: 92
A7: 4000 | B7: 66 | C7: 66
A8: 5000 | B8: 25 | C8: 25
A9: Desktop | B9: 2 | C9: 2
A10: 2000 | B10: 1 | C10: 1
A11: 5000 | B11: 1 | C11: 1
A12: DESKTOP SCADAR | B12: 2 | C12: 2
A13: 2000 | B13: 2 | C13: 2
A14: Laptop | B14: 609 | C14: 609
A15: 1000 | B15: 87 | C15: 87
A16: 2000 | B16: 173 | C16: 173
A17: 4000 | B17: 314 | C17: 314
A18: 5000 | B18: 35 | C18: 35
A19: Machine Laptop | B19: 1 | C19: 1
A20: 2000 | B20: 1 | C20: 1
A21: SCARDA Desktop | B21: 2 | C21: 2
A22: 2000 | B22: 2 | C22: 2
A23: Server | B23: 9 | C23: 9
A24: 1000 | B24: 1 | C24: 1
A25: 2000 | B25: 1 | C25: 1
A26: 4000 | B26: 5 | C26: 5
A27: 5000 | B27: 2 | C27: 2
A28: Shared Desktop | B28: 74 | C28: 74
A29: 2000 | B29: 69 | C29: 69
A30: 4000 | B30: 3 | C30: 3
A31: 5000 | B31: 2 | C31: 2
A32: Grand Total | B32: 888 | C32: 888

Sheet Premier-Antivirus-Sheet
A3: S.no | B3: Hostname | C3: Serial numbers | D3: Rough IP | E3: Sap Code | F3: Laptop/Desktop | G3: Laptop or Desktop | H3: Employee Name | I3: Employee ID | J3: Department | K3: Location | L3: Sentinelone Uninstallation | M3: Trendmicro Installation | N3: Domain (Yes or No) | O3: Unauthorized App (Yes or No) | P3: Windows License (Yes or No) | Q3: Remarks | R3: As per Capex Team | S3: Company Name | T3: Company Code | U3: Mapped | V3: Unicode | W3: Make
A4: 1 | B4: DESKTOP-4L4V6II | C4: 2FCYXY3 | D4: Corrected | E4: 32000139 | F4: Desktop | G4: Desktop | H4: Line System | J4: RFID Technical | K4: P4 | L4: Yes | M4: Yes | N4: No | O4: No | P4: Yes | R4: 4500013144 | S4: PEIPL | T4: 5000 | U4: Yes | V4: 500032000139 | W4: #N/A | X4: #N/A
A5: =A4+1 -> 2 | B5: DT-HEEVDO4 | C5: HEEVDO4 | D5: TECHNICAL-1 | E5: 32000013 | F5: Desktop | G5: Desktop | H5: TECHNICAL-1 | I5: General | J5: General | K5: P4 | L5: yes | M5: Yes | N5: yes | O5: yes | P5: yes | Q5: Ultraviewer | R5: =_xlfn.XLOOKUP(C5,'[1]Detailed file'!$M:$M,'[1]Detailed file'!$M:$M) -> #N/A | S5: PEIPL | T5: 5000 | U5: Yes | V5: 500032000013 | W5: #N/A | X5: #N/A
A6: =A5+1 -> 3 | B6: DT-43KWMZ3 | C6: 43KWMZ3 | D6: Corrected | E6: 32000017 | F6: Desktop | G6: Desktop | H6: NIKHIL | I6: PEIPL0718 | J6: Quality | K6: P4 | L6: Yes | M6: Yes | N6: Yes | O6: Yes | P6: Yes | Q6: Uninstalled Ultrviewer | R6: =_xlfn.XLOOKUP(C6,'[1]Detailed file'!$M:$M,'[1]Detailed file'!$M:$M) -> #N/A | S6: PEIPL | T6: 5000 | U6: Yes | V6: 500032000017 | W6: #N/A | X6: #N/A
A7: =A6+1 -> 4 | B7: PEGEPL-DT-43KWMZ3 | C7: 43KWMZ3 | D7: Corrected | E7: 32000018 | F7: Desktop | G7: Desktop | H7: UMADEVI | I7: PEGEPL0315 | J7: PDI | K7: P4 | L7: Yes | M7: Yes | N7: Yes | O7: Yes | P7: Yes | Q7: Uninstalled Ultrviewer | R7: =_xlfn.XLOOKUP(C7,'[1]Detailed file'!$M:$M,'[1]Detailed file'!$M:$M) -> #N/A | S7: PEIPL | T7: 5000 | U7: Yes | V7: 500032000018 | W7: #N/A | X7: #N/A
A8: =A7+1 -> 5 | B8: DESKTOP-794FE8T | C8: Assembled PC | D8: Pel | E8: 32000022 | F8: Shared Desktop | G8: Desktop | H8: General | I8: General | J8: General | K8: Corp | L8: Yes | M8: Yes | N8: Yes | O8: No | P8: Yes | R8: =_xlfn.XLOOKUP(C8,'[1]Detailed file'!$M:$M,'[1]Detailed file'!$M:$M) -> #N/A | S8: PEGEPL | T8: 4000 | U8: No | V8: 400032000022 | W8: #N/A | X8: #N/A
A9: =A8+1 -> 6 | B9: DESKTOP-C53GIU0 | C9: Assembled PC | D9: Corrected | E9: 32000017 | F9: Desktop | G9: Desktop | H9: Rework Area Line-1 System | I9: Machine System | J9: Rework | K9: P4 | L9: Yes | M9: Yes | N9: Yes | O9: No | P9: Yes | Q9: Uninstalled Anydesk | R9: =_xlfn.XLOOKUP(C9,'[1]Detailed file'!$M:$M,'[1]Detailed file'!$M:$M) -> #N/A | S9: PEIPL | T9: 5000 | U9: No | V9: 500032000017 | W9: #N/A | X9: #N/A
A10: =A9+1 -> 7 | B10: P2-DT-FGOFFICE1 | C10: Assembled pc | D10: Verified | E10: 32000180 | F10: Desktop | G10: Desktop | H10: General | I10: General | J10: FG Stores | K10: P2 | L10: YES | M10: YES | N10: YES | O10: No | P10: YES | R10: =_xlfn.XLOOKUP(C10,'[1]Detailed file'!$M:$M,'[1]Detailed file'!$M:$M) -> #N/A | S10: PEPPL | T10: 2000 | U10: No | V10: 200032000180 | W10: #N/A | X10: #N/A
A11: =A10+1 -> 8 | B11: P2-DT-HXF52M | C11: Assembled PC | D11: Verified | E11: 32000181 | F11: Desktop | G11: Desktop | H11: Nelli Tejasree | I11: General | J11: Finance & Accounts | K11: P2 | L11: YES | M11: YES | N11: YES | O11: No | P11: YES | R11: =_xlfn.XLOOKUP(C11,'[1]Detailed file'!$M:$M,'[1]Detailed file'!$M:$M) -> #N/A | S11: PEPPL | T11: 2000 | U11: No | V11: 200032000181 | W11: #N/A | X11: #N/A
A12: =A11+1 -> 9 | B12: P2-DT-O6T56BO | C12: Assembled PC | D12: Verified | E12: 32000182 | F12: Shared Desktop | G12: Desktop | H12: General | I12: General | J12: FG Stores | K12: P2 | L12: Yes | M12: Yes | N12: YES | O12: YES | P12: Yes | Q12: Ultraviewer | R12: =_xlfn.XLOOKUP(C12,'[1]Detailed file'!$M:$M,'[1]Detailed file'!$M:$M) -> #N/A | S12: PEPPL | T12: 2000 | U12: No | V12: 200032000182 | W12: #N/A | X12: #N/A
A13: =A12+1 -> 10 | B13: P2-DT-QUALITY1 | C13: Assembled PC | D13: Verified | E13: 32000183 | F13: Desktop | G13: Desktop | H13: General | I13: General | J13: Module line-Quality lab | K13: P2 | L13: YES | M13: YES | N13: YES | O13: No | P13: YES | R13: =_xlfn.XLOOKUP(C13,'[1]Detailed file'!$M:$M,'[1]Detailed file'!$M:$M) -> #N/A | S13: PEPPL | T13: 2000 | U13: No | V13: 200032000183 | W13: #N/A | X13: #N/A
A14: =A13+1 -> 11 | B14: P2-SAFETY-01 | C14: Assembled PC | D14: DONE | E14: 32000184 | F14: Shared Desktop | G14: Desktop | H14: Safety -HR | I14: Safety -HR | J14: Safety | K14: P2 | L14: YES | M14: YES | N14: YES | O14: No | P14: YES | R14: =_xlfn.XLOOKUP(C14,'[1]Detailed file'!$M:$M,'[1]Detailed file'!$M:$M) -> #N/A | S14: PEPPL | T14: 2000 | U14: No | V14: 200032000184 | W14: #N/A | X14: #N/A
A15: =A14+1 -> 12 | B15: P4-DT-PEGEPL0164 | C15: Assembled PC | E15: 32000018 | F15: Desktop | G15: Desktop | H15: Common System | I15: Common System | J15: FG Stores | K15: P4 | L15: Yes | M15: Yes | N15: Yes | O15: No | P15: Yes | R15: =_xlfn.XLOOKUP(C15,'[1]Detailed file'!$M:$M,'[1]Detailed file'!$M:$M) -> #N/A | S15: PEIPL | T15: 5000 | U15: No | V15: 500032000018 | W15: #N/A | X15: #N/A
A16: =A15+1 -> 13 | B16: DESKTOP-D865K23 | C16: F22SMZ3 | D16: Corrected | E16: 32000135 | F16: Desktop | G16: Desktop | H16: D.SHASHIDHAR REDDY | I16: PEGEPL0294 | J16: Gate | K16: P4 | L16: Yes | M16: Yes | N16: Yes | O16: Yes | P16: Yes | Q16: Uninstalled Ultrviewer | R16: =_xlfn.XLOOKUP(C16,'[1]Detailed file'!$M:$M,'[1]Detailed file'!$M:$M) -> #N/A | S16: PEIPL | T16: 5000 | U16: Yes | V16: 500032000135 | W16: #N/A | X16: #N/A
A17: =A16+1 -> 14 | B17: PESSPL26 | C17: PG04EZZA | D17: Done | E17: 32000214 | F17: Laptop | G17: Laptop | H17: Smarth Salaria | I17: PESSPL0014 | J17: Engineering | K17: Pune | L17: Yes | M17: Yes | N17: No | O17: Yes | P17: Yes | R17: 4510000604 | S17: PEL | T17: 1000 | U17: Yes | V17: 100032000214 | W17: Lenovo | X17: 4510000193
A18: =A17+1 -> 15 | B18: DT-10BNM24 | C18: 10BNM24 | D18: Corrected | E18: 32000022 | F18: Desktop | G18: Desktop | H18: NAVEEN | I18: PEIPL0567 | J18: Quality | K18: P4 | L18: Yes | M18: Yes | N18: Yes | O18: Yes | P18: Yes | Q18: Uninstalled Ultrviewer | R18: 4500022659 | S18: PEIPL | T18: 5000 | U18: Yes | V18: 500032000022 | W18: Dell | X18: 4500022659
A19: =A18+1 -> 16 | B19: P4-LT-PEIPL0585 | C19: 10H7X93 | D19: Corrected | E19: 32000053 | F19: Laptop | G19: Laptop | H19: Ramesh | I19: PEIPL20938 | J19: STORES | K19: P4 | L19: Yes | M19: Yes | N19: No | O19: No | P19: Yes | R19: =_xlfn.XLOOKUP(C19,'[1]Detailed file'!$M:$M,'[1]Detailed file'!$M:$M) -> #N/A | S19: PEIPL | T19: 5000 | U19: Yes | V19: 500032000053 | W19: =_xlfn.XLOOKUP(A19,[1]Cut2!$A:$A,[1]Cut2!$S:$S) -> #N/A | X19: #N/A
A20: =A19+1 -> 17 | B20: P6-DT-JOGQUPS | C20: 1761N24 | D20: Verification Done-P6 | E20: 32000125 | F20: Desktop | G20: Desktop | H20: SHIVA BABU | I20: PEGEPL0117 | J20: PRODUCTION | K20: P6 | L20: Yes | M20: Yes | N20: NO | O20: Yes | P20: Yes | Q20: Uninstalled Ultrviewer | R20: 4510000023 | S20: PEGEPL | T20: 4000 | U20: Yes | V20: 400032000125 | W20: #N/A | X20: #N/A
A21: =A20+1 -> 18 | B21: LT-184TG63 | C21: 184TG63 | D21: Corrected | E21: 32000055 | F21: Laptop | G21: Laptop | H21: K.SHRAVANI | I21: PEIPL601 | J21: Admin | K21: P4 | L21: Yes | M21: Yes | N21: Yes | O21: Yes | P21: Yes | Q21: Uninstalled Ultrviewer | R21: =_xlfn.XLOOKUP(C21,'[1]Detailed file'!$M:$M,'[1]Detailed file'!$M:$M) -> #N/A | S21: PEIPL | T21: 5000 | U21: Yes | V21: 500032000055 | W21: =_xlfn.XLOOKUP(A21,[1]Cut2!$A:$A,[1]Cut2!$S:$S) -> #N/A | X21: #N/A
A22: =A21+1 -> 19 | B22: P2-DT-1CZRPT3 | C22: 1CZRPT3 | D22: Verified(general) | E22: 32000136 | F22: Desktop | G22: Desktop | H22: Kethavath Manoj | I22: PEPPL0419 | J22: MODULE QTY | K22: P2 | L22: Yes | M22: Yes | N22: yes | O22: Yes | P22: Yes | Q22: Ultraviewer | R22: =_xlfn.XLOOKUP(C22,'[1]Detailed file'!$M:$M,'[1]Detailed file'!$M:$M) -> #N/A | S22: PEPPL | T22: 2000 | U22: Yes | V22: 200032000136 | W22: #N/A | X22: #N/A
A23: =A22+1 -> 20 | B23: P6-DT-GTE99R2 | C23: 1D42N24 | D23: Verification Done-P6 | E23: 32000113 | F23: Desktop | G23: Desktop | H23: Boge Thirumala | I23: PEGEPL0170 | J23: STORE | K23: P6 | L23: Yes | M23: Yes | N23: NO | O23: Yes | P23: Yes | Q23: Uninstalled Ultrviewer | R23: 4510000023 | S23: PEGEPL | T23: 4000 | U23: Yes | V23: 400032000113 | W23: #N/A | X23: #N/A
A24: =A23+1 -> 21 | B24: P6-DT-815ATSA | C24: 1G42N24 | D24: Verification Done-P6 | E24: 32000134 | F24: Desktop | G24: Desktop | H24: RAMAKANTH | I24: General | J24: FQC | K24: P6 | L24: Yes | M24: Yes | N24: NO | O24: Yes | P24: Yes | Q24: Uninstalled Ultrviewer | R24: 4510000023 | S24: PEGEPL | T24: 4000 | U24: Yes | V24: 400032000134 | W24: #N/A | X24: #N/A
A25: =A24+1 -> 22 | B25: PEL-1GPHNV2 | C25: 1GPHNV2 | D25: Done | E25: 32000230 | F25: Laptop | G25: Laptop | H25: Chikkala Pravallika | I25: PEGEPL0158 | J25: Finance & Accounts | K25: Corp | L25: Yes | M25: Yes | N25: Yes | O25: Yes | P25: Yes | Q25: Uninstalled Ultraviewer | R25: =_xlfn.XLOOKUP(C25,'[1]Detailed file'!$M:$M,'[1]Detailed file'!$M:$M) -> #N/A | S25: PEGEPL | T25: 4000 | U25: Yes | V25: 400032000230 | W25: =_xlfn.XLOOKUP(A25,[1]Cut2!$A:$A,[1]Cut2!$S:$S) -> #N/A | X25: #N/A
A26: =A25+1 -> 23 | B26: P6-DT-RAB2N60 | C26: 1HQ2N24 | D26: Verification Done-P6 | E26: 32000111 | F26: Desktop | G26: Desktop | H26: SURESH | I26: 10004788 | J26: HR | K26: P6 | L26: Yes | M26: Yes | N26: NO | O26: Yes | P26: Yes | Q26: Uninstalled Ultrviewer | R26: 4510000023 | S26: PEGEPL | T26: 4000 | U26: Yes | V26: 400032000111 | W26: #N/A | X26: #N/A
A27: =A26+1 -> 24 | B27: DT-1HZVMZ3 | C27: 1HZVMZ3 | D27: Corrected | E27: 32000023 | F27: Desktop | G27: Desktop | H27: KALYAN | I27: PEGEP0067 | J27: Packaging | K27: P4 | L27: Yes | M27: Yes | N27: Yes | O27: Yes | P27: Yes | Q27: Uninstalled Ultrviewer | R27: =_xlfn.XLOOKUP(C27,'[1]Detailed file'!$M:$M,'[1]Detailed file'!$M:$M) -> #N/A | S27: PEIPL | T27: 5000 | U27: Yes | V27: 500032000023 | W27: Dell | X27: 4500016124
A28: =A27+1 -> 25 | B28: P2-DT-1JYPKW3 | C28: 1JYPKW3 | D28: Verified(General) | E28: 32000142 | F28: Shared Desktop | G28: Desktop | H28: General | I28: General | J28: Production cell 1 | K28: P2 | L28: Yes | M28: Yes | N28: YES | O28: Yes | P28: Yes | Q28: Ultraviewer | R28: 4500009822 | S28: PEPPL | T28: 2000 | U28: Yes | V28: 200032000142 | W28: Dell | X28: 4500009822
A29: =A28+1 -> 26 | B29: P6-DT-DHTHSO4 | C29: 1LG3N24 | D29: Verification Done-P6 | E29: 32000131 | F29: Desktop | G29: Desktop | H29: VISHESH YASHEEL | I29: PEIPL0508 | J29: TECHNICAL | K29: P6 | L29: Yes | M29: Yes | N29: NO | O29: Yes | P29: Yes | Q29: Uninstalled Ultrviewer | R29: 4510000023 | S29: PEGEPL | T29: 4000 | U29: Yes | V29: 400032000131 | W29: #N/A | X29: #N/A
A30: =A29+1 -> 27 | B30: P2-LT-1N142602D5 | C30: 1N142602D5 | D30: Verified | E30: 32000331 | F30: Laptop | G30: Laptop | H30: Durga kumar avvaru | I30: PEPPL0125 | J30: Safety | K30: P2 | L30: Yes | M30: Yes | N30: Yes | O30: No | P30: Yes | R30: 4510000005 | S30: PEPPL | T30: 2000 | U30: Yes | V30: 200032000331 | W30: HP | X30: 4510000005
A31: =A30+1 -> 28 | B31: PEG-1N142602DC | C31: 1N142602DC | D31: Done | E31: 32000269 | F31: Laptop | G31: Laptop | H31: Prtyusha | I31: PSS1286 | J31: Finance | K31: Corp | L31: Yes | M31: Yes | N31: Yes | O31: Yes | P31: Yes | Q31: Uninstalled Ultraviewer | R31: =_xlfn.XLOOKUP(C31,'[1]Detailed file'!$M:$M,'[1]Detailed file'!$M:$M) -> 1N142602DC | S31: PEGEPL | T31: 4000 | U31: Yes | V31: 400032000269 | W31: HP | X31: 4510001061
A32: =A31+1 -> 29 | B32: P6-LT-1N142602JB | C32: 1N142602JB | D32: Verification Done-P6 | E32: 32000095 | F32: Laptop | G32: Laptop | H32: J.NAVEEN BABU | I32: 50984 | J32: QUALITY(IQC) | K32: P6 | L32: YES | M32: Yes | N32: NO | O32: YES | P32: Yes | Q32: Uninstalled Ultrviewer | R32: 4510000024 | S32: PEGEPL | T32: 4000 | U32: Yes | V32: 400032000095 | W32: HP | X32: 4510000024
A33: =A32+1 -> 30 | B33: P6-LT-1N142602JG | C33: 1N142602JG | D33: Verification Done-P6 | E33: 32000093 | F33: Laptop | G33: Laptop | H33: RAMESH BABU | I33: PEIPL0676 | J33: SAFETY | K33: P6 | L33: YES | M33: Yes | N33: NO | O33: YES | P33: Yes | Q33: Uninstalled Ultrviewer | R33: 4510000024 | S33: PEGEPL | T33: 4000 | U33: Yes | V33: 400032000093 | W33: HP | X33: 4510000024
A34: =A33+1 -> 31 | B34: P6-LT-1N142602JP | C34: 1N142602JP | D34: Verification Done-P6 | E34: 32000094 | F34: Laptop | G34: Laptop | H34: ANAND GUPTA | I34: PEGEPL0375 | J34: TECHINICAL | K34: P6 | L34: YES | M34: YES | N34: NO | O34: YES | P34: YES | Q34: Uninstalled Ultrviewer | R34: 4510000024 | S34: PEGEPL | T34: 4000 | U34: Yes | V34: 400032000094 | W34: HP | X34: 4510000024
A35: =A34+1 -> 32 | B35: PEIPL1N142602K1 | C35: 1N142602K1 | D35: Done | E35: 32000270 | F35: Laptop | G35: Laptop | H35: BHASKAR REDDY | I35: PEGEPL0488 | J35: Procurement | K35: Corp | L35: Yes | M35: Yes | N35: Yes | O35: No | P35: Yes | R35: =_xlfn.XLOOKUP(C35,'[1]Detailed file'!$M:$M,'[1]Detailed file'!$M:$M) -> 1N142602K1 | S35: PEGEPL | T35: 4000 | U35: Yes | V35: 400032000270 | W35: HP | X35: 4510000052
A36: =A35+1 -> 33 | B36: PEG1N142602MK | C36: 1N142602MK | D36: Done | E36: 32000061 | F36: Laptop | G36: Laptop | H36: Koppula Akshith | I36: PEGEPL0328 | J36: Projects | K36: Corp | L36: Yes | M36: Yes | N36: Yes | O36: No | P36: Yes | R36: =_xlfn.XLOOKUP(C36,'[1]Detailed file'!$M:$M,'[1]Detailed file'!$M:$M) -> 1N142602MK | S36: PEGEPL | T36: 4000 | U36: Yes | V36: 400032000061 | W36: HP | X36: 4510000053
A37: =A36+1 -> 34 | B37: P6-LT-1N142602MR | C37: 1N142602MR | D37: Verification Done-P6 | E37: 32000105 | F37: Laptop | G37: Laptop | H37: G.ASHOK | I37: PEG9LI099 | J37: STORE | K37: P6 | L37: YES | M37: Yes | N37: NO | O37: Yes | P37: Yes | R37: 4510000024 | S37: PEGEPL | T37: 4000 | U37: Yes | V37: 400032000105 | W37: HP | X37: 4510000024
A38: =A37+1 -> 35 | B38: P6-LT-1N142602NX | C38: 1N142602NX | D38: Verification Done-P6 | E38: 32000107 | F38: Laptop | G38: Laptop | H38: SHIBANEE PATNAIK | I38: PEGEPL0374 | J38: TECHINICAL | K38: P6 | L38: YES | M38: YES | N38: NO | O38: YES | P38: Yes | Q38: Uninstalled Ultrviewer | R38: 4510000024 | S38: PEGEPL | T38: 4000 | U38: Yes | V38: 400032000107 | W38: HP | X38: 4510000024
A39: =A38+1 -> 36 | B39: PEG1N142602P3 | C39: 1N142602P3 | D39: DONE | E39: 32000006 | F39: Laptop | G39: Laptop | H39: Vasi Sree Mahalakshmi | I39: PSS1432 | J39: Finance & Accounts | K39: Corp | L39: Yes | M39: Yes | N39: Yes | O39: No | P39: Yes | Q39: Uninstalled Ultrviewer | R39: =_xlfn.XLOOKUP(C39,'[1]Detailed file'!$M:$M,'[1]Detailed file'!$M:$M) -> 1N142602P3 | S39: PEGEPL | T39: 4000 | U39: Yes | V39: 400032000006 | W39: HP | X39: 4510000053
A40: =A39+1 -> 37 | B40: PEIPL1N142602PB | C40: 1N142602PB | D40: Done | E40: 32000063 | F40: Laptop | G40: Laptop | H40: Mukul Prabhat Banka | I40: PEGEPL0300 | J40: Projects | K40: Corp | L40: Yes | M40: Yes | N40: Yes | O40: Yes | P40: Yes | Q40: Uninstalled Ultraviewer | R40: =_xlfn.XLOOKUP(C40,'[1]Detailed file'!$M:$M,'[1]Detailed file'!$M:$M) -> 1N142602PB | S40: PEGEPL | T40: 4000 | U40: Yes | V40: 400032000063 | W40: HP | X40: 4510000052
A41: =A40+1 -> 38 | B41: P6-LT-1N142602PZ | C41: 1N142602PZ | D41: Corrected | E41: 32000108 | F41: Laptop | G41: Laptop | H41: DINESH | I41: PEIPL0498 | J41: QUALITY | K41: P6 | L41: YES | M41: Yes | N41: NO | O41: YES | P41: Yes | Q41: Uninstalled Ultrviewer | R41: 4510000024 | S41: PEGEPL | T41: 4000 | U41: Yes | V41: 400032000108 | W41: HP | X41: 4510000024
A42: =A41+1 -> 39 | B42: P6-LT-1N142602QJ | C42: 1N142602QJ | D42: Verification Done-P6 | E42: 32000103 | F42: Laptop | G42: Laptop | H42: SHRISHAIL DINDURE | I42: PEGEPL0436 | J42: MAINTAETANCE | K42: P6 | L42: YES | M42: YES | N42: NO | O42: YES | P42: Yes | R42: 4510000024 | S42: PEGEPL | T42: 4000 | U42: Yes | V42: 400032000103 | W42: HP | X42: 4510000024
...

Sheet Cut2
A2: S.no | B2: Hostname | C2: Serial numbers | D2: Rough IP | E2: Sap Code | F2: Laptop/Desktop | G2: Laptop or Desktop | H2: Location | I2: As per Capex Team | J2: Company Name | K2: Mapped | L2: Make
A3: 2 | B3: DT-HEEVDO4 | C3: HEEVDO4 | D3: TECHNICAL-1 | F3: Desktop | G3: Desktop | H3: P4 | I3: #N/A | J3: PEIPL | K3: Yes | L3: #N/A
A4: 3 | B4: DT-43KWMZ3 | C4: 43KWMZ3 | D4: Corrected | F4: Desktop | G4: Desktop | H4: P4 | I4: #N/A | J4: PEIPL | K4: Yes | L4: #N/A
A5: 4 | B5: PEGEPL-DT-43KWMZ3 | C5: 43KWMZ3 | D5: Corrected | F5: Desktop | G5: Desktop | H5: P4 | I5: #N/A | J5: PEIPL | K5: Yes | L5: #N/A
A6: 13 | B6: DESKTOP-D865K23 | C6: F22SMZ3 | D6: Corrected | E6: 32000006 | F6: Desktop | G6: Desktop | H6: P4 | I6: #N/A | J6: PEIPL | K6: Yes | L6: #N/A
A7: 19 | B7: P2-DT-1CZRPT3 | C7: 1CZRPT3 | D7: Verified(general) | F7: Desktop | G7: Desktop | H7: P2 | I7: #N/A | J7: PEPPL | K7: Yes | L7: #N/A
A8: 24 | B8: DT-1HZVMZ3 | C8: 1HZVMZ3 | D8: Corrected | F8: Desktop | G8: Desktop | H8: P4 | I8: #N/A | J8: PEIPL | K8: Yes | L8: Dell
A9: 115 | B9: P2-D-1N145106PC | C9: 1N145106PC | D9: Verified | F9: Desktop | G9: Desktop | H9: P2 | I9: #N/A | J9: PEPPL | K9: Yes | L9: HP
A10: 213 | B10: P2-DT-1VZ3324 | C10: 1VZ3324 | D10: Verified | E10: 32000294 | F10: Desktop | G10: Desktop | H10: P2 | I10: #N/A | J10: PEPPL | K10: Yes | L10: Dell
A11: 214 | B11: P2-DT-1X8TXK3 | C11: 1X8TXK3 | D11: Verified | F11: Desktop | G11: Desktop | H11: P2 | I11: #N/A | J11: PEPPL | K11: Yes | L11: #N/A
A12: 217 | B12: P2-DT-22M3VK3 | C12: 22M3VK3 | D12: Verified | F12: Desktop | G12: Desktop | H12: P2 | I12: #N/A | J12: PEPPL | K12: Yes | L12: #N/A
A13: 223 | B13: DESKTOP-2K91SB8 | C13: 28ZTVM3 | D13: Verified | F13: Desktop | G13: Desktop | H13: P2 | I13: #N/A | J13: PEPPL | K13: Yes | L13: #N/A
A14: 229 | B14: DT-2MMRMZ3 | C14: 2MMRMZ3 | D14: Corrected | E14: 32000006 | F14: Desktop | G14: Desktop | H14: P4 | I14: #N/A | J14: PEIPL | K14: Yes | L14: Dell
A15: 233 | B15: DESKTOP-O9GOHCR | C15: 2TJ8FP2 | D15: Verified | F15: Desktop | G15: Desktop | H15: City Office | I15: #N/A | J15: PEGEPL | K15: Yes | L15: #N/A
A16: 245 | B16: DT-3GZVMZ3 | C16: 3GZVMZ3 | D16: Corrected | F16: Desktop | G16: Desktop | H16: P4 | I16: #N/A | J16: PEIPL | K16: Yes | L16: #N/A
A17: 247 | B17: DT-3L49FVH | C17: 3L49FVH | D17: Corrected | F17: Desktop | G17: Desktop | H17: P4 | I17: #N/A | J17: PEIPL | K17: Yes | L17: #N/A
A18: 262 | B18: DT-47IUQAC | C18: 47IUQAC | D18: Corrected | F18: Desktop | G18: Desktop | H18: P4 | I18: #N/A | J18: PEIPL | K18: Yes | L18: #N/A
A19: 271 | C19: 52TZ914 | D19: Verified(mission connection) | F19: Desktop | G19: Desktop | H19: P2 | I19: #N/A | J19: PEPPL | K19: Yes | L19: #N/A
A20: 272 | C20: 52X0B14 | D20: Done | F20: Desktop | G20: Desktop | H20: P2 | I20: #N/A | J20: PEPPL | K20: Yes | L20: #N/A
A21: 274 | B21: P3-DT-57PZGW3 | C21: 57PZGW3 | D21: Verified | E21: 32000023 | F21: Desktop | G21: Desktop | H21: P2 | I21: #N/A | J21: PEPPL | K21: Yes | L21: #N/A
A22: 277 | B22: P2-DT-5BZRPT3 | C22: 5BZRPT3 | D22: Verified(general) | F22: Desktop | G22: Desktop | H22: P2 | I22: #N/A | J22: PEPPL | K22: Yes | L22: #N/A
A23: 281 | B23: DESKTOP-EP5O9FV | C23: 5CG83353XD | D23: Verified | F23: Desktop | G23: Desktop | H23: P2 | I23: #N/A | J23: PEPPL | K23: Yes | L23: #N/A
A24: 283 | B24: P6-DT-C54P89E | C24: 5GQ2N24 | D24: Verification Done-P6 | F24: Desktop | G24: Desktop | H24: P6 | I24: #N/A | J24: PEGEPL | K24: Yes | L24: #N/A
A25: 288 | B25: P2-DT-5NVHJB3 | C25: 5NVHJB3 | D25: Verified | F25: Shared Desktop | G25: Desktop | H25: P2 | I25: #N/A | J25: PEPPL | K25: Yes | L25: #N/A
A26: 289 | C26: 5P4VBP3 | D26: Done | F26: Desktop | G26: Desktop | H26: P2 | I26: #N/A | J26: PEPPL | K26: Yes | L26: #N/A
A27: 292 | B27: DESKTOP-KUBDH36 | C27: 5XZTVM3 | D27: Done | F27: Desktop | G27: Desktop | H27: P2 | I27: #N/A | J27: PEPPL | K27: Yes | L27: #N/A
A28: 299 | B28: P2-DT-68C34G3 | C28: 68C34G3 | D28: DONE | F28: Desktop | G28: Desktop | H28: P2 | I28: #N/A | J28: PEPPL | K28: Yes | L28: #N/A
A29: 303 | B29: P2-LT-6FPZGW3 | C29: 6FPZGW3 | D29: Verified | F29: Desktop | G29: Desktop | H29: P2 | I29: #N/A | J29: PEPPL | K29: Yes | L29: #N/A
A30: 306 | B30: P2-DT-6MPJDB2 | C30: 6MPJDB2 | D30: Verified | F30: Desktop | G30: Desktop | H30: City Office | I30: #N/A | J30: PEGEPL | K30: Yes | L30: #N/A
A31: 307 | B31: PEIPL-DT-6NND8BS | C31: 6NND8BS | D31: Verified | F31: Desktop | G31: Desktop | H31: P2 | I31: #N/A | J31: PEPPL | K31: Yes | L31: #N/A
A32: 310 | B32: DESKTOP-4HCLSGK | C32: 6PZTVM3 | D32: DONE | F32: Desktop | G32: Desktop | H32: P2 | I32: #N/A | J32: PEPPL | K32: Yes | L32: #N/A
A33: 311 | B33: P2-DT-6QTWM24 | C33: 6QTWM24 | D33: Verified | F33: Desktop | G33: Desktop | H33: P2 | I33: #N/A | J33: PEPPL | K33: Yes | L33: Dell
A34: 313 | B34: PEPPL-DT-6W8TXK | C34: 6W8TXK | D34: Verified | F34: Shared Desktop | G34: Desktop | H34: P2 | I34: #N/A | J34: PEPPL | K34: Yes | L34: #N/A
A35: 314 | B35: PEPPL-DT-6W8TXK3 | C35: 6W8TXK3 | D35: Verified | F35: Desktop | G35: Desktop | H35: P2 | I35: #N/A | J35: PEPPL | K35: Yes | L35: #N/A
A36: 315 | B36: DT-C7JEGJ3 | C36: 6YSVMZ3 | D36: Corrected | F36: Desktop | G36: Desktop | H36: P4 | I36: #N/A | J36: PEIPL | K36: Yes | L36: #N/A
A37: 319 | B37: P2-DT-769TXK3 | C37: 769TXK3 | D37: Verified(general) | F37: Desktop | G37: Desktop | H37: P2 | I37: #N/A | J37: PEPPL | K37: Yes | L37: #N/A
A38: 320 | B38: P2-DT-ASPBK04 | C38: 798X5V2 | D38: Verified(correct) | F38: Desktop | G38: Desktop | H38: P2 | I38: #N/A | J38: PEPPL | K38: Yes | L38: #N/A
A39: 324 | B39: DT-7GZVMZ3 | C39: 7GZVMZ3 | D39: Corrected | F39: Desktop | G39: Desktop | H39: P4 | I39: #N/A | J39: PEIPL | K39: Yes | L39: #N/A
A40: 329 | B40: P6-DT-I9GFHPU | C40: 7NLMN24 | D40: Verification Done-P6 | F40: Desktop | G40: Desktop | H40: P6 | I40: #N/A | J40: PEGEPL | K40: Yes | L40: #N/A
A41: 334 | B41: P2-DT-7YZ3324 | C41: 7YZ3324 | D41: Verified | E41: 32000291 | F41: Shared Desktop | G41: Desktop | H41: P2 | I41: #N/A | J41: PEPPL | K41: Yes | L41: Dell
...

Sheet Sheet1
C1: S.no | D1: Serial Number | E1: Model | F1: Status | G1: AS per Capex | H1: AS per Antivirus File | I1: Laptop Holder
C2: 1 | D2: 19kkJZ2 | E2: Dell | F2: IN REPAIR | G2: #N/A | H2: =_xlfn.XLOOKUP(D2,'Premier-Antivirus-Sheet'!C:C,'Premier-Antivirus-Sheet'!C:C) -> 19kkJZ2
C3: =C2+1 -> 2 | D3: CND92936QS | E3: HP | F3: IN REPAIR | G3: #N/A | H3: =_xlfn.XLOOKUP(D3,'Premier-Antivirus-Sheet'!C:C,'Premier-Antivirus-Sheet'!C:C) -> CND92936QS
C4: =C3+1 -> 3 | D4: CNDO121R5F | E4: HP | F4: IN REPAIR | G4: #N/A | H4: =_xlfn.XLOOKUP(D4,'Premier-Antivirus-Sheet'!C:C,'Premier-Antivirus-Sheet'!C:C) -> CNDO121R5F
C5: =C4+1 -> 4 | D5: CND1331QFK | E5: HP | F5: IN REPAIR | G5: #N/A | H5: =_xlfn.XLOOKUP(D5,'Premier-Antivirus-Sheet'!C:C,'Premier-Antivirus-Sheet'!C:C) -> CND1331QFK
C6: =C5+1 -> 5 | D6: DXYQNV2 | E6: Dell | F6: IN REPAIR | G6: DXYQNV2 | H6: =_xlfn.XLOOKUP(D6,'Premier-Antivirus-Sheet'!C:C,'Premier-Antivirus-Sheet'!C:C) -> DXYQNV2
C7: =C6+1 -> 6 | D7: DLRL142 | E7: Dell | F7: IN REPAIR | G7: #N/A | H7: =_xlfn.XLOOKUP(D7,'Premier-Antivirus-Sheet'!C:C,'Premier-Antivirus-Sheet'!C:C) -> DLRL142
C8: =C7+1 -> 7 | D8: RM9Y1A00 | E8: Dell | F8: IN REPAIR | G8: #N/A | H8: =_xlfn.XLOOKUP(D8,'Premier-Antivirus-Sheet'!C:C,'Premier-Antivirus-Sheet'!C:C) -> RM9Y1A00
C9: =C8+1 -> 8 | D9: 1DD11X2 | E9: Dell | F9: IN REPAIR | G9: #N/A | H9: =_xlfn.XLOOKUP(D9,'Premier-Antivirus-Sheet'!C:C,'Premier-Antivirus-Sheet'!C:C) -> 1DD11X2
C10: =C9+1 -> 9 | D10: 2TJ8FP2 | E10: Dell | F10: IN REPAIR | G10: #N/A | H10: =_xlfn.XLOOKUP(D10,'Premier-Antivirus-Sheet'!C:C,'Premier-Antivirus-Sheet'!C:C) -> 2TJ8FP2
C11: =C10+1 -> 10 | D11: H49XVF2 | E11: Dell | F11: IN REPAIR | G11: #N/A | H11: =_xlfn.XLOOKUP(D11,'Premier-Antivirus-Sheet'!C:C,'Premier-Antivirus-Sheet'!C:C) -> H49XVF2
C12: =C11+1 -> 11 | D12: 3CK51X2 | E12: Dell | F12: IN REPAIR | G12: #N/A | H12: =_xlfn.XLOOKUP(D12,'Premier-Antivirus-Sheet'!C:C,'Premier-Antivirus-Sheet'!C:C) -> 3CK51X2
C13: =C12+1 -> 12 | D13: 4Z02GC2 | E13: Dell | F13: IN REPAIR | G13: #N/A | H13: =_xlfn.XLOOKUP(D13,'Premier-Antivirus-Sheet'!C:C,'Premier-Antivirus-Sheet'!C:C) -> 4Z02GC2
C14: =C13+1 -> 13 | D14: JZ85B53 | E14: Dell | F14: IN REPAIR | G14: #N/A | H14: =_xlfn.XLOOKUP(D14,'Premier-Antivirus-Sheet'!C:C,'Premier-Antivirus-Sheet'!C:C) -> JZ85B53
C15: =C14+1 -> 14 | D15: J3ML2B3 | E15: Dell | F15: IN REPAIR | G15: #N/A | H15: =_xlfn.XLOOKUP(D15,'Premier-Antivirus-Sheet'!C:C,'Premier-Antivirus-Sheet'!C:C) -> J3ML2B3
C16: =C15+1 -> 15 | D16: 5470662 | E16: Dell Vostro 3458 | F16: IN REPAIR | G16: #N/A | H16: =_xlfn.XLOOKUP(D16,'Premier-Antivirus-Sheet'!C:C,'Premier-Antivirus-Sheet'!C:C) -> 5470662
C17: =C16+1 -> 16 | D17: CND0283N1M | E17: HP | F17: IN REPAIR | G17: #N/A | H17: =_xlfn.XLOOKUP(D17,'Premier-Antivirus-Sheet'!C:C,'Premier-Antivirus-Sheet'!C:C) -> CND0283N1M
C18: =C17+1 -> 17 | D18: JFKZMQ2 | E18: Dell | F18: IN REPAIR | G18: #N/A | H18: =_xlfn.XLOOKUP(D18,'Premier-Antivirus-Sheet'!C:C,'Premier-Antivirus-Sheet'!C:C) -> JFKZMQ2
C19: =C18+1 -> 18 | D19: 9VXMSQ2 | E19: Dell | F19: IN REPAIR | G19: 9VXMSQ2 | H19: =_xlfn.XLOOKUP(D19,'Premier-Antivirus-Sheet'!C:C,'Premier-Antivirus-Sheet'!C:C) -> 9VXMSQ2
C20: =C19+1 -> 19 | D20: FKZS5Q2 | E20: Dell | F20: IN REPAIR | G20: #N/A | H20: =_xlfn.XLOOKUP(D20,'Premier-Antivirus-Sheet'!C:C,'Premier-Antivirus-Sheet'!C:C) -> FKZS5Q2
C21: =C20+1 -> 20 | D21: CND1331RC0 | E21: HP 250 G8 Notebook PC (53L45PA) | F21: IN REPAIR | G21: #N/A | H21: =_xlfn.XLOOKUP(D21,'Premier-Antivirus-Sheet'!C:C,'Premier-Antivirus-Sheet'!C:C) -> CND1331RC0
C22: =C21+1 -> 21 | D22: No Searial number | E22: Dell | F22: IN REPAIR | G22: #N/A | H22: =_xlfn.XLOOKUP(D22,'Premier-Antivirus-Sheet'!C:C,'Premier-Antivirus-Sheet'!C:C) -> #N/A
C23: =C22+1 -> 22 | D23: No Searial number | E23: LENOVO | F23: IN REPAIR | G23: #N/A | H23: =_xlfn.XLOOKUP(D23,'Premier-Antivirus-Sheet'!C:C,'Premier-Antivirus-Sheet'!C:C) -> #N/A
C24: =C23+1 -> 23 | D24: No Searial number | E24: HP | F24: IN REPAIR | G24: #N/A | H24: =_xlfn.XLOOKUP(D24,'Premier-Antivirus-Sheet'!C:C,'Premier-Antivirus-Sheet'!C:C) -> #N/A
C25: =C24+1 -> 24 | D25: No Searial number | E25: HP | F25: IN REPAIR | G25: #N/A | H25: =_xlfn.XLOOKUP(D25,'Premier-Antivirus-Sheet'!C:C,'Premier-Antivirus-Sheet'!C:C) -> #N/A
C26: =C25+1 -> 25 | D26: B888P24 | E26: Desktop | F26: NORTH GATE ASSIGNED | G26: B888P24 | H26: =_xlfn.XLOOKUP(D26,'Premier-Antivirus-Sheet'!C:C,'Premier-Antivirus-Sheet'!C:C) -> B888P24
C27: =C26+1 -> 26 | D27: 8288P24 | E27: Desktop | F27: YET TO ASSIGN | G27: 8288P24 | H27: =_xlfn.XLOOKUP(D27,'Premier-Antivirus-Sheet'!C:C,'Premier-Antivirus-Sheet'!C:C) -> 8288P24 | I27: =_xlfn.XLOOKUP(D27,'Premier-Antivirus-Sheet'!C:C,'Premier-Antivirus-Sheet'!H:H) -> Anshika Dwivedi
C28: =C27+1 -> 27 | D28: 1Y26P24 | E28: Desktop | F28: YET TO ASSIGN | G28: 1Y26P24 | H28: =_xlfn.XLOOKUP(D28,'Premier-Antivirus-Sheet'!C:C,'Premier-Antivirus-Sheet'!C:C) -> 1Y26P24 | I28: =_xlfn.XLOOKUP(D28,'Premier-Antivirus-Sheet'!C:C,'Premier-Antivirus-Sheet'!H:H) -> Dhiraj sharma
C29: =C28+1 -> 28 | D29: 3188P24 | E29: Desktop | F29: YET TO ASSIGN | G29: 3188P24 | H29: =_xlfn.XLOOKUP(D29,'Premier-Antivirus-Sheet'!C:C,'Premier-Antivirus-Sheet'!C:C) -> 3188P24
C30: =C29+1 -> 29 | D30: 6188P24 | E30: Desktop | F30: YET TO ASSIGN | G30: 6188P24 | H30: =_xlfn.XLOOKUP(D30,'Premier-Antivirus-Sheet'!C:C,'Premier-Antivirus-Sheet'!C:C) -> 6188P24
C31: =C30+1 -> 30 | D31: C888P24 | E31: Desktop | F31: YET TO ASSIGN | G31: C888P24 | H31: =_xlfn.XLOOKUP(D31,'Premier-Antivirus-Sheet'!C:C,'Premier-Antivirus-Sheet'!C:C) -> C888P24
C32: =C31+1 -> 31 | D32: C188P24 | E32: Desktop | F32: YET TO ASSIGN | G32: C188P24 | H32: =_xlfn.XLOOKUP(D32,'Premier-Antivirus-Sheet'!C:C,'Premier-Antivirus-Sheet'!C:C) -> C188P24 | I32: =_xlfn.XLOOKUP(D32,'Premier-Antivirus-Sheet'!C:C,'Premier-Antivirus-Sheet'!H:H) -> B Anil Kumar
C33: =C32+1 -> 32 | D33: 7288P24 | E33: Desktop | F33: YET TO ASSIGN | G33: 7288P24 | H33: =_xlfn.XLOOKUP(D33,'Premier-Antivirus-Sheet'!C:C,'Premier-Antivirus-Sheet'!C:C) -> 7288P24
C34: =C33+1 -> 33 | D34: 8DZG384 | E34: Laptop | F34: IN REPAIR | G34: 8DZG384 | H34: =_xlfn.XLOOKUP(D34,'Premier-Antivirus-Sheet'!C:C,'Premier-Antivirus-Sheet'!C:C) -> 8DZG384 | I34: =_xlfn.XLOOKUP(D34,'Premier-Antivirus-Sheet'!C:C,'Premier-Antivirus-Sheet'!H:H) -> IT STOCK
C35: =C34+1 -> 34 | D35: BDZG384 | E35: Laptop | F35: OEM SERVICE Call | G35: BDZG384 | H35: =_xlfn.XLOOKUP(D35,'Premier-Antivirus-Sheet'!C:C,'Premier-Antivirus-Sheet'!C:C) -> BDZG384 | I35: =_xlfn.XLOOKUP(D35,'Premier-Antivirus-Sheet'!C:C,'Premier-Antivirus-Sheet'!H:H) -> Bandarupalli Krishna Chaitanya
C36: =C35+1 -> 35 | D36: JDZG384 | E36: Laptop | F36: IN REPAIR | G36: JDZG384 | H36: =_xlfn.XLOOKUP(D36,'Premier-Antivirus-Sheet'!C:C,'Premier-Antivirus-Sheet'!C:C) -> JDZG384 | I36: =_xlfn.XLOOKUP(D36,'Premier-Antivirus-Sheet'!C:C,'Premier-Antivirus-Sheet'!H:H) -> IT STOCK
C37: =C36+1 -> 36 | D37: 2DZG384 | E37: Laptop | F37: IN REPAIR | G37: 2DZG384 | H37: =_xlfn.XLOOKUP(D37,'Premier-Antivirus-Sheet'!C:C,'Premier-Antivirus-Sheet'!C:C) -> 2DZG384 | I37: =_xlfn.XLOOKUP(D37,'Premier-Antivirus-Sheet'!C:C,'Premier-Antivirus-Sheet'!H:H) -> IT STOCK
C38: =C37+1 -> 37 | D38: 6DZG384 | E38: Laptop | F38: IN REPAIR | G38: 6DZG384 | H38: =_xlfn.XLOOKUP(D38,'Premier-Antivirus-Sheet'!C:C,'Premier-Antivirus-Sheet'!C:C) -> 6DZG384 | I38: =_xlfn.XLOOKUP(D38,'Premier-Antivirus-Sheet'!C:C,'Premier-Antivirus-Sheet'!H:H) -> IT STOCK
C39: =C38+1 -> 38 | D39: DDZG384 | E39: Laptop | F39: IN REPAIR | G39: DDZG384 | H39: =_xlfn.XLOOKUP(D39,'Premier-Antivirus-Sheet'!C:C,'Premier-Antivirus-Sheet'!C:C) -> DDZG384 | I39: =_xlfn.XLOOKUP(D39,'Premier-Antivirus-Sheet'!C:C,'Premier-Antivirus-Sheet'!H:H) -> IT STOCK
C40: =C39+1 -> 39 | D40: HL5NQ74 | E40: Laptop | F40: IN REPAIR | G40: HL5NQ74 | H40: =_xlfn.XLOOKUP(D40,'Premier-Antivirus-Sheet'!C:C,'Premier-Antivirus-Sheet'!C:C) -> HL5NQ74 | I40: =_xlfn.XLOOKUP(D40,'Premier-Antivirus-Sheet'!C:C,'Premier-Antivirus-Sheet'!H:H) -> IT STOCK
...

Sheet End Point Report
A1: Endpoint name | B1: Object type | C1: Protection Manager | D1: Status
A2: PELFS01 | B2: Server | C2: Enpoint Protection | D2: Completed
A3: PELDHCP01 | B3: Server | C3: Enpoint Protection | D3: Completed
A4: PELDC01 | B4: Server | C4: Enpoint Protection | D4: Completed
A5: P4-AD-SERVER | B5: Server | C5: Enpoint Protection | D5: Completed
A6: PELSRV01 | B6: Server | C6: Enpoint Protection | D6: Completed
A7: PEIPL-STOR-S1 | B7: Server | C7: Enpoint Protection | D7: Completed
A8: PELKFINTECH | B8: Server | C8: Enpoint Protection | D8: Completed
A9: PEL-BNKTR | B9: Desktop | C9: Enpoint Protection | D9: Completed
A10: PEL-SCM | B10: Server | C10: Enpoint Protection | D10: Completed
A11: PEPPLSRV01 | B11: Server | C11: Enpoint Protection | D11: Completed
A12: PEIPL-MES-P4 | B12: Server | C12: Enpoint Protection | D12: Completed
... A579: PEL-MP2FV7FY | B579: Desktop | C579: Enpoint Protection | D579: Completed
