Workbook

Sheet Inputs
B2: Project Assumption | F2: Project Execution timeline | I2: Financial Assumptions
B3: Total number of pallet position | C3: # | D3: 8928 | F3: Start Date | G3: 45566 | I3: Company Name | J3: PPGPL | L3: Assumption List
B4: Project Life | D4: 15 | F4: # of months | G4: 14 | I4: Cost of Capital | J4: =J6*9.5%*(1-J5)+J7*20% -> 0.0710904 | L4: Sr. No. | M4: Parameters | N4: Value | O4: UOM | P4: Remarks
F5: End Date | G5: =EOMONTH(G3,G4-1) -> 45991 | I5: Tax Rate | J5: =22%*(1+4%)*(1+10%) -> 0.25168 | L5: A | M5: Project
B6: Charges to the customer | F6: End of Project | G6: =EOMONTH(G5,D4*12)+1 -> 51471 | I6: Debt | J6: 1 | L6: 1 | M6: Project life | N6: =D4 -> 15 | O6: years
B7: Security Deposit from consumer | C7: months | D7: 3 | I7: Equity | J7: =MAX(1-J6,0.0000000001%) -> 1e-12 | L7: 2 | M7: Number of pallet position | N7: =D3 -> 8928 | O7: # | P7: Based on current planning
B8: Storage Utilisation | C8: % | D8: ='Warehouse Inventory '!I18 -> 0.83990912 | L8: 3 | M8: Rent per pallet per day | N8: =D10 -> 67.827523 | O8: Rs./day/pallet | P8: In reference to Radiant and Kothur warehouse rentals
B9: Markup from market cost | D9: 0.15 | L9: 4 | M9: Term of rent agreement | N9: =D12 -> 7 | O9: years
B10: Rent per pallet per day | C10: Rs./pallet/day | D10: =D22*(1+D9) -> 67.827523 | L10: 5 | M10: Storage duration of each pallet | N10: =D8 -> 0.83990912 | O10: days | P10: Material will be outbound within this days
B11: Escalation | C11: every year | D11: 0.05 | L11: 6 | M11: Inventory Turnover | N11: =D13 -> 0 | O11: times
B12: Rent renewal/Term of agreement | C12: every ___ years | D12: 7 | L12: 7 | M12: Start of Project Execution | N12: =G3 -> 45566
L13: 8 | M13: End of Project Execution | N13: =G5 -> 45991
L14: 9 | M14: Land | P14: As per the land lease rental of HSTL <> PEPPL Gas yard and Kothur lease rental
L15: a | M15: Total land required | N15: ='Project Expenses'!F36 -> 248396 | O15: sq. ft. | P15: As per the diagram
B16: Returns | L16: b | M16: Land lease rental | N16: ='Project Expenses'!F37 -> 16 | O16: Rs./sq. ft./month
B17: IRR | C17: =IRR!C24 -> 0.13098165 | D17: % | L17: c | M17: Security deposit on land | N17: 3 | O17: months
B18: NPV | C18: =IRR!C25 -> 66.396621 | D18: crore | L18: d | M18: Term of land rental | N18: 7 | O18: years
B19: Payback period | C19: =IRR!C26 -> 5.1618635 | D19: years | L19: e | M19: Escalation
B20: ROCE-Post Tax | C20: =IRR!C28 -> 0.35581103 | D20: % | E20: =1/C20 -> 2.8104806 | M20: Yr 1 | N20: 0 | O20: %
M21: Yr 2 | N21: 0 | O21: %
B22: Warehousing cost | C22: =C10 -> Rs./pallet/day | D22: =F47 -> 58.980455 | M22: Yr 3 | N22: 0.05 | O22: %
M23: Yr 4 | N23: 0.05 | O23: %
M24: Yr 5 | N24: 0.05 | O24: %
B25: Warehouse | D25: Area (Sqft) | E25: Rate/Sqft | F25: Rent per month | G25: Storage Capacity (Pallets) | H25: Rate/Pallet | I25: Rate per pallet per day | M25: Yr 6 | N25: 0.05 | O25: %
B26: Kothur | D26: ='Kothur Reference'!C2 -> 261597.18 | E26: ='Kothur Reference'!C6 -> 23 | F26: ='Kothur Reference'!C7 -> 7099747.5 | G26: ='Kothur Reference'!C3 -> 9354.8387 | H26: =F26/G26 -> 758.93852 | I26: =H26/30 -> 25.297951 | M26: Yr 7 | N26: 0.05 | O26: %
B27: Radiant | D27: ='Radiant Reference'!C2 -> 71858 | E27: ='Radiant Reference'!C6 -> 22 | F27: ='Radiant Reference'!C7 -> 1865433.7 | G27: ='Radiant Reference'!C3 -> 2902.9032 | H27: =F27/G27 -> 642.60967 | I27: =H27/30 -> 21.420322 | L27: B | M27: Financial
B28: Weighted Average | D28: =SUM(D26:D27) -> 333455.18 | E28: =F28/D28 -> 26.885716 | F28: =SUM(F26:F27) -> 8965181.1 | G28: =SUM(G26:G27) -> 12257.742 | H28: =F28/G28 -> 731.38929 | I28: =H28/30 -> 24.379643 | L28: 1 | M28: Total project cost | N28: ='Project Cost Details'!G35/10^7 -> 54.166044 | O28: Rs. Crore
B29: Transportation Cost to be factored (factory to Kottur) | F29: ='Kothur Reference'!C42/12 -> 5162500 | H29: =F29/G26 -> 551.85345 | I29: =F29/G26/30 -> 18.395115 | L29: a | M29: Debt | N29: ='Project Cost Details'!G38/10^7 -> 54.166044 | O29: Rs. Crore
B30: Transportation Cost to be factored (factory to Radiant) | F30: ='Radiant Reference'!C42/12 -> 171100 | H30: =F30/G27 -> 58.940993 | I30: =F30/G27/30 -> 1.9646998 | L30: b | M30: Equity | N30: ='Project Cost Details'!G39/10^7 -> 5.4166044e-11 | O30: Rs. Crore
B31: Storages Charges cost per pallet | H31: =H28+H29+H30 -> 1342.1837 | I31: =I28+I29+I30 -> 44.739458 | L31: 2 | M31: WACC | N31: =J4 -> 0.0710904 | O31: %
B32: Operational Charges | L32: 3 | M32: Tax Rate | N32: =J5 -> 0.25168 | O32: %
B33: Manpower | D33: =D36 -> 333455.18 | E33: =F33/D33 -> 2.2101921 | F33: =(('Radiant Reference'!E19)+'Kothur Reference'!E19)/12 -> 737000 | G33: =G28 -> 12257.742 | H33: =F33/G33 -> 60.125266 | I33: =H33/30 -> 2.0041755 | L33: 4 | M33: Depreciation term | N33: ='Project Expenses'!C51 -> 7.5 | O33: years
B34: IT assets | D34: =D33 -> 333455.18 | E34: =F34/D34 -> 0.088967479 | F34: =('Radiant Reference'!E26+'Kothur Reference'!E26)/12 -> 29666.667 | G34: =G33 -> 12257.742 | H34: =F34/G34 -> 2.4202391 | I34: =H34/30 -> 0.080674638
B35: Machineries | D35: =D34 -> 333455.18 | E35: =F35/D35 -> 4.3433798 | F35: =('Radiant Reference'!E32+'Kothur Reference'!E32)/12 -> 1448322.5 | G35: =G34 -> 12257.742 | H35: =F35/G35 -> 118.15573 | I35: =H35/30 -> 3.9385245
B36: Total Operational charges per pallet | D36: =D28 -> 333455.18 | E36: =F36/D36 -> 6.6425394 | F36: =SUM(F33:F35) -> 2214989.2 | G36: =G28 -> 12257.742 | H36: =F36/G36 -> 180.70124 | I36: =H36/30 -> 6.0233747
B37: Markup @ 15% | F37: =D9 -> 0.15 | H37: =(H31+H36)*15% -> 228.43275 | I37: =(I31+I36)*F37 -> 7.6144248
B38: Gajwel charges per pallet per day | H38: =H31+H37+H36 -> 1751.3177 | I38: =I31+I37+I36 -> 58.377257
B39: No of pallets capacity | I39: =D3 -> 8928 | P39: =5000*7 -> 35000
B40: Occupancy | H40: ='Warehouse Inventory '!I18 -> 0.83990912 | I40: =I39*H40 -> 7498.7086
B41: Revenue to Gajwel per annum | D41: 6696*49.93*365 | H41: Rs in Crs | I41: =(I38*I40*365)/10^7 -> 15.978023
...

Sheet IRR
B2: Type | C2: =IF(C4<=Inputs!$G$5,"Cons","Beyond Cons") -> Cons | D2: =IF(D4<=Inputs!$G$5,"Cons","Beyond Cons") -> Cons | E2: =IF(E4<=Inputs!$G$5,"Cons","Beyond Cons") -> Cons | F2: =IF(F4<=Inputs!$G$5,"Cons","Beyond Cons") -> Cons | G2: =IF(G4<=Inputs!$G$5,"Cons","Beyond Cons") -> Cons | H2: =IF(H4<=Inputs!$G$5,"Cons","Beyond Cons") -> Cons | I2: =IF(I4<=Inputs!$G$5,"Cons","Beyond Cons") -> Cons | J2: =IF(J4<=Inputs!$G$5,"Cons","Beyond Cons") -> Cons | ... BA2: =IF(BA4<=Inputs!$G$5,"Cons","Beyond Cons") -> Beyond Cons
B3: Start Month | C3: =Inputs!G3 -> 45566 | D3: =IFERROR(IF(C4+1<Inputs!$G$6,C4+1,"-"),"-") -> 45597 | E3: =IFERROR(IF(D4+1<Inputs!$G$6,D4+1,"-"),"-") -> 45627 | F3: =IFERROR(IF(E4+1<Inputs!$G$6,E4+1,"-"),"-") -> 45658 | G3: =IFERROR(IF(F4+1<Inputs!$G$6,F4+1,"-"),"-") -> 45689 | H3: =IFERROR(IF(G4+1<Inputs!$G$6,G4+1,"-"),"-") -> 45717 | I3: =IFERROR(IF(H4+1<Inputs!$G$6,H4+1,"-"),"-") -> 45748 | J3: =IFERROR(IF(I4+1<Inputs!$G$6,I4+1,"-"),"-") -> 45778 | K3: =IFERROR(IF(J4+1<Inputs!$G$6,J4+1,"-"),"-") -> 45809 | ... BA3: =IFERROR(IF(AZ4+1<Inputs!$G$6,AZ4+1,"-"),"-") -> -
B4: End Month | C4: =EOMONTH(C3,0.5) -> 45596 | D4: =IFERROR(IF(EOMONTH(D3,0.5)<=Inputs!$G$5,EOMONTH(D3,0.5),EOMONTH(D3,11)),"-") -> 45626 | E4: =IFERROR(IF(EOMONTH(E3,0.5)<=Inputs!$G$5,EOMONTH(E3,0.5),EOMONTH(E3,11)),"-") -> 45657 | F4: =IFERROR(IF(EOMONTH(F3,0.5)<=Inputs!$G$5,EOMONTH(F3,0.5),EOMONTH(F3,11)),"-") -> 45688 | G4: =IFERROR(IF(EOMONTH(G3,0.5)<=Inputs!$G$5,EOMONTH(G3,0.5),EOMONTH(G3,11)),"-") -> 45716 | H4: =IFERROR(IF(EOMONTH(H3,0.5)<=Inputs!$G$5,EOMONTH(H3,0.5),EOMONTH(H3,11)),"-") -> 45747 | I4: =IFERROR(IF(EOMONTH(I3,0.5)<=Inputs!$G$5,EOMONTH(I3,0.5),EOMONTH(I3,11)),"-") -> 45777 | J4: =IFERROR(IF(EOMONTH(J3,0.5)<=Inputs!$G$5,EOMONTH(J3,0.5),EOMONTH(J3,11)),"-") -> 45808 | K4: =IFERROR(IF(EOMONTH(K3,0.5)<=Inputs!$G$5,EOMONTH(K3,0.5),EOMONTH(K3,11)),"-") -> 45838 | ... BA4: =IFERROR(IF(EOMONTH(BA3,0.5)<=Inputs!$G$5,EOMONTH(BA3,0.5),EOMONTH(BA3,11)),"-") -> -
B5: Days | C5: =_xlfn.DAYS(C4,C3)+1 -> 31 | D5: =IFERROR(_xlfn.DAYS(D4,D3)+1,0) -> 30 | E5: =IFERROR(_xlfn.DAYS(E4,E3)+1,0) -> 31 | F5: =IFERROR(_xlfn.DAYS(F4,F3)+1,0) -> 31 | G5: =IFERROR(_xlfn.DAYS(G4,G3)+1,0) -> 28 | H5: =IFERROR(_xlfn.DAYS(H4,H3)+1,0) -> 31 | I5: =IFERROR(_xlfn.DAYS(I4,I3)+1,0) -> 30 | J5: =IFERROR(_xlfn.DAYS(J4,J3)+1,0) -> 31 | K5: =IFERROR(_xlfn.DAYS(K4,K3)+1,0) -> 30 | ... BA5: =IFERROR(_xlfn.DAYS(BA4,BA3)+1,0) -> 0
B6: Count | C6: =IF(C2="Cons",0,1) -> 0 | D6: =IF(D2="Cons",0,MAX(C6+1,Inputs!D4)) -> 0 | E6: =IF(E2="Cons",0,MAX(D6+1,Inputs!E7)) -> 0 | F6: =IF(F2="Cons",0,MAX(E6+1,Inputs!F7)) -> 0 | G6: =IF(G2="Cons",0,MAX(F6+1,Inputs!G7)) -> 0 | H6: =IF(H2="Cons",0,MAX(G6+1,Inputs!H7)) -> 0 | I6: =IF(I2="Cons",0,MAX(H6+1,Inputs!I7)) -> 0 | J6: =IF(J2="Cons",0,MAX(I6+1,Inputs!J7)) -> 0 | K6: =IF(K2="Cons",0,MAX(J6+1,Inputs!K7)) -> 0 | L6: =IF(L2="Cons",0,MAX(K6+1,Inputs!L7)) -> 0 | ... BA6: =IF(BA2="Cons",0,MAX(AZ6+1,Inputs!BA7)) -> 37
B8: CAPEX
B9: Outflows | C9: =IF(C2="Cons",_xlfn.XLOOKUP(C3,'Project Capex'!$E$2:$AG$2,'Project Capex'!$E$69:$AG$69),0) -> 15.600953 | D9: =IF(D2="Cons",_xlfn.XLOOKUP(D3,'Project Capex'!$E$2:$AG$2,'Project Capex'!$E$69:$AG$69),0) -> 0.30095298 | E9: =IF(E2="Cons",_xlfn.XLOOKUP(E3,'Project Capex'!$E$2:$AG$2,'Project Capex'!$E$69:$AG$69),0) -> 0.30095298 | F9: =IF(F2="Cons",_xlfn.XLOOKUP(F3,'Project Capex'!$E$2:$AG$2,'Project Capex'!$E$69:$AG$69),0) -> 0.30095298 | G9: =IF(G2="Cons",_xlfn.XLOOKUP(G3,'Project Capex'!$E$2:$AG$2,'Project Capex'!$E$69:$AG$69),0) -> 0.80403491 | H9: =IF(H2="Cons",_xlfn.XLOOKUP(H3,'Project Capex'!$E$2:$AG$2,'Project Capex'!$E$69:$AG$69),0) -> 1.657997 | I9: =IF(I2="Cons",_xlfn.XLOOKUP(I3,'Project Capex'!$E$2:$AG$2,'Project Capex'!$E$69:$AG$69),0) -> 2.9820605 | J9: =IF(J2="Cons",_xlfn.XLOOKUP(J3,'Project Capex'!$E$2:$AG$2,'Project Capex'!$E$69:$AG$69),0) -> 8.409215 | ... BA9: =IF(BA2="Cons",_xlfn.XLOOKUP(BA3,'Project Capex'!$E$2:$AG$2,'Project Capex'!$E$69:$AG$69),0) -> 0
B11: Inflows
A12: =AVERAGE(Q12:AE12) -> 13.38543 | B12: FCF | C12: =IF(C2="Cons",0,_xlfn.XLOOKUP(C3,Computations!$C$4:$AG$4,Computations!$C$67:$AG$67)) -> 0 | D12: =IF(D2="Cons",0,_xlfn.XLOOKUP(D3,Computations!$C$4:$AG$4,Computations!$C$67:$AG$67)) -> 0 | E12: =IF(E2="Cons",0,_xlfn.XLOOKUP(E3,Computations!$C$4:$AG$4,Computations!$C$67:$AG$67)) -> 0 | F12: =IF(F2="Cons",0,_xlfn.XLOOKUP(F3,Computations!$C$4:$AG$4,Computations!$C$67:$AG$67)) -> 0 | G12: =IF(G2="Cons",0,_xlfn.XLOOKUP(G3,Computations!$C$4:$AG$4,Computations!$C$67:$AG$67)) -> 0 | H12: =IF(H2="Cons",0,_xlfn.XLOOKUP(H3,Computations!$C$4:$AG$4,Computations!$C$67:$AG$67)) -> 0 | I12: =IF(I2="Cons",0,_xlfn.XLOOKUP(I3,Computations!$C$4:$AG$4,Computations!$C$67:$AG$67)) -> 0 | J12: =IF(J2="Cons",0,_xlfn.XLOOKUP(J3,Computations!$C$4:$AG$4,Computations!$C$67:$AG$67)) -> 0 | ... BA12: =IF(BA2="Cons",0,_xlfn.XLOOKUP(BA3,Computations!$C$4:$AG$4,Computations!$C$67:$AG$67)) -> 0
B14: Net Cashflow | C14: =IFERROR(C12-C9,0) -> -15.600953 | D14: =IFERROR(D12-D9,0) -> -0.30095298 | E14: =IFERROR(E12-E9,0) -> -0.30095298 | F14: =IFERROR(F12-F9,0) -> -0.30095298 | G14: =IFERROR(G12-G9,0) -> -0.80403491 | H14: =IFERROR(H12-H9,0) -> -1.657997 | I14: =IFERROR(I12-I9,0) -> -2.9820605 | J14: =IFERROR(J12-J9,0) -> -8.409215 | ... BA14: =IFERROR(BA12-BA9,0) -> 0
B15: Cummulative CF | C15: =C14 -> -15.600953 | D15: =D14+C15 -> -15.901906 | E15: =E14+D15 -> -16.202859 | F15: =F14+E15 -> -16.503812 | G15: =G14+F15 -> -17.307847 | H15: =H14+G15 -> -18.965844 | I15: =I14+H15 -> -21.947904 | J15: =J14+I15 -> -30.357119 | K15: =K14+J15 -> -35.354272 | ... AL15: =AL14+AK15 -> 146.61541
A16: =Inputs!J4 -> 0.0710904 | B16: Discount factor | C16: =1/(1+$A$16)^C6 -> 1 | D16: =1/(1+$A$16)^D6 -> 1 | E16: =1/(1+$A$16)^E6 -> 1 | F16: =1/(1+$A$16)^F6 -> 1 | G16: =1/(1+$A$16)^G6 -> 1 | H16: =1/(1+$A$16)^H6 -> 1 | I16: =1/(1+$A$16)^I6 -> 1 | J16: =1/(1+$A$16)^J6 -> 1 | ... BA16: =1/(1+$A$16)^BA6 -> 0.078783144
B17: Discounted Cash flow | C17: =C14*C16 -> -15.600953 | D17: =D14*D16 -> -0.30095298 | E17: =E14*E16 -> -0.30095298 | F17: =F14*F16 -> -0.30095298 | G17: =G14*G16 -> -0.80403491 | H17: =H14*H16 -> -1.657997 | I17: =I14*I16 -> -2.9820605 | J17: =J14*J16 -> -8.409215 | ... BA17: =BA14*BA16 -> 0
B18: Cummulative DCF | C18: =C17 -> -15.600953 | D18: =D17+C18 -> -15.901906 | E18: =E17+D18 -> -16.202859 | F18: =F17+E18 -> -16.503812 | G18: =G17+F18 -> -17.307847 | H18: =H17+G18 -> -18.965844 | I18: =I17+H18 -> -21.947904 | J18: =J17+I18 -> -30.357119 | K18: =K17+J18 -> -35.354272 | ... AN18: =AN17+AM18 -> 66.396621
B19: For payback Cummulative DCF | C19: =IFERROR(-_xlfn.XLOOKUP(C3,'Project Capex'!$E$2:$AG$2,'Project Capex'!$E$69:$AG$69)*C16,_xlfn.XLOOKUP(C3,'Project Capex'!$E$2:$AG$2,'Project Capex'!$E$69:$AG$69)*C16+C15) -> -15.600953 | D19: =IFERROR(-_xlfn.XLOOKUP(D3,'Project Capex'!$E$2:$AG$2,'Project Capex'!$E$69:$AG$69)*D16,D17)+C19 -> -15.901906 | E19: =IFERROR(-_xlfn.XLOOKUP(E3,'Project Capex'!$E$2:$AG$2,'Project Capex'!$E$69:$AG$69)*E16,E17)+D19 -> -16.202859 | F19: =IFERROR(-_xlfn.XLOOKUP(F3,'Project Capex'!$E$2:$AG$2,'Project Capex'!$E$69:$AG$69)*F16,F17)+E19 -> -16.503812 | G19: =IFERROR(-_xlfn.XLOOKUP(G3,'Project Capex'!$E$2:$AG$2,'Project Capex'!$E$69:$AG$69)*G16,G17)+F19 -> -17.307847 | H19: =IFERROR(-_xlfn.XLOOKUP(H3,'Project Capex'!$E$2:$AG$2,'Project Capex'!$E$69:$AG$69)*H16,H17)+G19 -> -18.965844 | I19: =IFERROR(-_xlfn.XLOOKUP(I3,'Project Capex'!$E$2:$AG$2,'Project Capex'!$E$69:$AG$69)*I16,I17)+H19 -> -21.947904 | J19: =IFERROR(-_xlfn.XLOOKUP(J3,'Project Capex'!$E$2:$AG$2,'Project Capex'!$E$69:$AG$69)*J16,J17)+I19 -> -30.357119 | K19: =IFERROR(-_xlfn.XLOOKUP(K3,'Project Capex'!$E$2:$AG$2,'Project Capex'!$E$69:$AG$69)*K16,K17)+J19 -> -35.354272 | ... AN19: =IFERROR(-_xlfn.XLOOKUP(AN3,'Project Capex'!$E$2:$AG$2,'Project Capex'!$E$69:$AG$69)*AN16,AN17)+AM19 -> 66.396621
B20: Payback | C20: 0 | D20: {=_xlfn.IFS(AND(D2="Beyond Cons",C2="Cons"),1,AND(D2="Cons",C2="Cons"),0,AND(D2="Beyond Cons",C2="Beyond Cons"),IF(AND(D18<0,D6>1),D6,IF(AND(C20<1,D6>0),0,-C18/D17)))} -> 0 | E20: {=_xlfn.IFS(AND(E2="Beyond Cons",D2="Cons"),1,AND(E2="Cons",D2="Cons"),0,AND(E2="Beyond Cons",D2="Beyond Cons"),IF(AND(E18<0,E6>1),E6,IF(AND(D20<1,E6>0),0,-D18/E17)))} -> 0 | F20: {=_xlfn.IFS(AND(F2="Beyond Cons",E2="Cons"),1,AND(F2="Cons",E2="Cons"),0,AND(F2="Beyond Cons",E2="Beyond Cons"),IF(AND(F18<0,F6>1),F6,IF(AND(E20<1,F6>0),0,-E18/F17)))} -> 0 | G20: {=_xlfn.IFS(AND(G2="Beyond Cons",F2="Cons"),1,AND(G2="Cons",F2="Cons"),0,AND(G2="Beyond Cons",F2="Beyond Cons"),IF(AND(G18<0,G6>1),G6,IF(AND(F20<1,G6>0),0,-F18/G17)))} -> 0 | H20: {=_xlfn.IFS(AND(H2="Beyond Cons",G2="Cons"),1,AND(H2="Cons",G2="Cons"),0,AND(H2="Beyond Cons",G2="Beyond Cons"),IF(AND(H18<0,H6>1),H6,IF(AND(G20<1,H6>0),0,-G18/H17)))} -> 0 | I20: {=_xlfn.IFS(AND(I2="Beyond Cons",H2="Cons"),1,AND(I2="Cons",H2="Cons"),0,AND(I2="Beyond Cons",H2="Beyond Cons"),IF(AND(I18<0,I6>1),I6,IF(AND(H20<1,I6>0),0,-H18/I17)))} -> 0 | J20: {=_xlfn.IFS(AND(J2="Beyond Cons",I2="Cons"),1,AND(J2="Cons",I2="Cons"),0,AND(J2="Beyond Cons",I2="Beyond Cons"),IF(AND(J18<0,J6>1),J6,IF(AND(I20<1,J6>0),0,-I18/J17)))} -> 0 | K20: {=_xlfn.IFS(AND(K2="Beyond Cons",J2="Cons"),1,AND(K2="Cons",J2="Cons"),0,AND(K2="Beyond Cons",J2="Beyond Cons"),IF(AND(K18<0,K6>1),K6,IF(AND(J20<1,K6>0),0,-J18/K17)))} -> 0 | ... P20: {=_xlfn.IFS(AND(P2="Beyond Cons",O2="Cons"),1,AND(P2="Cons",O2="Cons"),0,AND(P2="Beyond Cons",O2="Beyond Cons"),IF(AND(P18<0,P6>1),P6,IF(AND(O20<1,P6>0),0,-O18/P17)))} -> 0 | Q20: {=_xlfn.IFS(AND(Q2="Beyond Cons",P2="Cons"),1,AND(Q2="Cons",P2="Cons"),0,AND(Q2="Beyond Cons",P2="Beyond Cons"),IF(AND(Q19<0,Q6>1),Q6,IF(AND(P20<1,Q6>0),0,-P19/Q17)))} -> 1 | R20: {=_xlfn.IFS(AND(R2="Beyond Cons",Q2="Cons"),1,AND(R2="Cons",Q2="Cons"),0,AND(R2="Beyond Cons",Q2="Beyond Cons"),IF(AND(R19<0,R6>1),R6,IF(AND(Q20<1,R6>0),0,-Q19/R17)))} -> 2 | S20: {=_xlfn.IFS(AND(S2="Beyond Cons",R2="Cons"),1,AND(S2="Cons",R2="Cons"),0,AND(S2="Beyond Cons",R2="Beyond Cons"),IF(AND(S19<0,S6>1),S6,IF(AND(R20<1,S6>0),0,-R19/S17)))} -> 3 | T20: {=_xlfn.IFS(AND(T2="Beyond Cons",S2="Cons"),1,AND(T2="Cons",S2="Cons"),0,AND(T2="Beyond Cons",S2="Beyond Cons"),IF(AND(T19<0,T6>1),T6,IF(AND(S20<1,T6>0),0,-S19/T17)))} -> 4 | U20: {=_xlfn.IFS(AND(U2="Beyond Cons",T2="Cons"),1,AND(U2="Cons",T2="Cons"),0,AND(U2="Beyond Cons",T2="Beyond Cons"),IF(AND(U19<0,U6>1),U6,IF(AND(T20<1,U6>0),0,-T19/U17)))} -> 5 | V20: {=_xlfn.IFS(AND(V2="Beyond Cons",U2="Cons"),1,AND(V2="Cons",U2="Cons"),0,AND(V2="Beyond Cons",U2="Beyond Cons"),IF(AND(V19<0,V6>1),V6,IF(AND(U20<1,V6>0),0,-U19/V17)))} -> 0.16186346 | W20: {=_xlfn.IFS(AND(W2="Beyond Cons",V2="Cons"),1,AND(W2="Cons",V2="Cons"),0,AND(W2="Beyond Cons",V2="Beyond Cons"),IF(AND(W19<0,W6>1),W6,IF(AND(V20<1,W6>0),0,-V19/W17)))} -> 0 | X20: {=_xlfn.IFS(AND(X2="Beyond Cons",W2="Cons"),1,AND(X2="Cons",W2="Cons"),0,AND(X2="Beyond Cons",W2="Beyond Cons"),IF(AND(X19<0,X6>1),X6,IF(AND(W20<1,X6>0),0,-W19/X17)))} -> 0 | ... BA20: {=_xlfn.IFS(AND(BA2="Beyond Cons",AZ2="Cons"),1,AND(BA2="Cons",AZ2="Cons"),0,AND(BA2="Beyond Cons",AZ2="Beyond Cons"),IF(AND(BA19<0,BA6>1),BA6,IF(AND(AZ20<1,BA6>0),0,-AZ19/BA17)))} -> 0
B21: Cummulative Payback | C21: 0 | D21: =IF(AND(D20<1,D20>0),C20+D20,0) -> 0 | E21: =IF(AND(E20<1,E20>0),D20+E20,0) -> 0 | F21: =IF(AND(F20<1,F20>0),E20+F20,0) -> 0 | G21: =IF(AND(G20<1,G20>0),F20+G20,0) -> 0 | H21: =IF(AND(H20<1,H20>0),G20+H20,0) -> 0 | I21: =IF(AND(I20<1,I20>0),H20+I20,0) -> 0 | J21: =IF(AND(J20<1,J20>0),I20+J20,0) -> 0 | K21: =IF(AND(K20<1,K20>0),J20+K20,0) -> 0 | ... BA21: =IF(AND(BA20<1,BA20>0),AZ20+BA20,0) -> 0
A23: =Inputs!J7 -> 1e-12 | B23: Equity | P23: =-SUM('Project Capex'!E72:R72) -> -5.4166044e-11 | Q23: =Q17 -> 9.5427751 | R23: =R17 -> 10.150766 | S23: =S17 -> 10.799431 | T23: =T17 -> 10.749805 | U23: =U17 -> 11.08989 | V23: =V17 -> 11.326693 | W23: =W17 -> 12.287297 | X23: =X17 -> 3.0537843 | ... AE23: =AE17 -> 2.1207593
B24: IRR | C24: =XIRR($C$17:$AE$17,$C$4:$AE$4) -> 0.13098165 | D24: %
B25: NPV | C25: =SUM(C17:BA17) -> 66.396621 | D25: Crore
B26: Payback | C26: =MAX(C21:BA21) -> 5.1618635 | D26: years
B27: ROCE - Pre Tax | C27: =AVERAGE(Computations!C27:Q27) -> 0.43830164 | D27: % | E27: =1/C27 -> 2.2815338
B28: ROCE - Post- Tax | C28: =(Computations!C26-Computations!C35+Computations!C36)/'Project Capex'!D69 -> 0.35581103 | D28: % | E28: =1/C28 -> 2.8104806
A30: 4.19 | B30: 0.05 | C30: -18.090992 | D30: -0.03699171 | E30: -0.03699171 | F30: -0.03699171 | G30: -0.54007364 | H30: -3.8364474 | I30: -3.6477917 | J30: -3.7316387 | K30: -3.7316387 | L30: -0.03699171 | M30: -0.03699171 | N30: -0.03699171 | O30: -0.03699171 | P30: -3.6687535 | Q30: 7.5767024 | R30: 8.4689324 | S30: 9.0390328 | T30: 9.561214 | U30: 10.148648 | V30: 4.2877924 | W30: 8.5556555 | X30: 8.4600074 | Y30: 9.3947628 | Z30: 9.9738746 | AA30: 4.1296406 | AB30: 7.6498117 | AC30: 8.141676 | AD30: 9.3357844 | AE30: 6.4705089 | AF30: 0 | AG30: 0 | AH30: 0 | AI30: 0 | AJ30: 0 | AK30: 0 | AL30: 0 | AM30: 0 | AN30: 0 | AO30: 0 | AP30: 0 | AQ30: 0 | AR30: 0 | AS30: 0 | AT30: 0 | AU30: 0 | AV30: 0 | AW30: 0 | AX30: 0 | AY30: 0 | AZ30: 0 | BA30: 0
A31: 4.28 | B31: 0.1 | C31: -18.090992 | D31: -0.03699171 | E31: -0.03699171 | F31: -0.03699171 | G31: -0.54007364 | H31: -3.8364474 | I31: -3.6477917 | J31: -3.7316387 | K31: -3.7316387 | L31: -0.03699171 | M31: -0.03699171 | N31: -0.03699171 | O31: -0.03699171 | P31: -3.6687535 | Q31: 8.1628147 | R31: 9.0843503 | S31: 9.6869968 | T31: 10.239712 | U31: 10.861071 | V31: 4.7273766 | W31: 9.1727641 | X31: 9.1061962 | Y31: 10.073261 | Z31: 10.686298 | AA31: 4.5704325 | AB31: 8.2652296 | AC31: 8.7878648 | AD31: 10.014283 | AE31: 7.0062941 | AF31: 0 | AG31: 0 | AH31: 0 | AI31: 0 | AJ31: 0 | AK31: 0 | AL31: 0 | AM31: 0 | AN31: 0 | AO31: 0 | AP31: 0 | AQ31: 0 | AR31: 0 | AS31: 0 | AT31: 0 | AU31: 0 | AV31: 0 | AW31: 0 | AX31: 0 | AY31: 0 | AZ31: 0 | BA31: 0
A32: 3.06 | B32: 0.15 | C32: -18.090992 | D32: -0.03699171 | E32: -0.03699171 | F32: -0.03699171 | G32: -0.54007364 | H32: -3.8364474 | I32: -3.6477917 | J32: -3.7316387 | K32: -3.7316387 | L32: -0.03699171 | M32: -0.03699171 | N32: -0.03699171 | O32: -0.03699171 | P32: -3.6687535 | Q32: 8.748927 | R32: 9.6997682 | S32: 10.334961 | T32: 10.91821 | U32: 11.573495 | V32: 5.1669608 | W32: 9.7898728 | X32: 9.752385 | Y32: 10.751759 | Z32: 11.398721 | AA32: 5.0112244 | AB32: 8.8806475 | AC32: 9.4340536 | AD32: 10.692781 | AE32: 7.5420794 | AF32: 0 | AG32: 0 | AH32: 0 | AI32: 0 | AJ32: 0 | AK32: 0 | AL32: 0 | AM32: 0 | AN32: 0 | AO32: 0 | AP32: 0 | AQ32: 0 | AR32: 0 | AS32: 0 | AT32: 0 | AU32: 0 | AV32: 0 | AW32: 0 | AX32: 0 | AY32: 0 | AZ32: 0 | BA32: 0
A33: 3.13 | B33: 0.2 | C33: -18.090992 | D33: -0.03699171 | E33: -0.03699171 | F33: -0.03699171 | G33: -0.54007364 | H33: -3.8364474 | I33: -3.6477917 | J33: -3.7316387 | K33: -3.7316387 | L33: -0.03699171 | M33: -0.03699171 | N33: -0.03699171 | O33: -0.03699171 | P33: -3.6687535 | Q33: 9.3350393 | R33: 10.315186 | S33: 10.982925 | T33: 11.596709 | U33: 12.285918 | V33: 5.606545 | W33: 10.406981 | X33: 10.398574 | Y33: 11.430258 | Z33: 12.111144 | AA33: 5.4520162 | AB33: 9.4960655 | AC33: 10.080242 | AD33: 11.371279 | AE33: 8.0778647 | AF33: 0 | AG33: 0 | AH33: 0 | AI33: 0 | AJ33: 0 | AK33: 0 | AL33: 0 | AM33: 0 | AN33: 0 | AO33: 0 | AP33: 0 | AQ33: 0 | AR33: 0 | AS33: 0 | AT33: 0 | AU33: 0 | AV33: 0 | AW33: 0 | AX33: 0 | AY33: 0 | AZ33: 0 | BA33: 0
D39: =1.0859/15 -> 0.072393333 | H39: =0.71*12 -> 8.52

Sheet Sensitivities
B2: IRR | C2: =IRR!#REF! -> #REF!
B3: NPV | C3: =IRR!C25 -> 66.396621
B4: Payback period | C4: =IRR!C26 -> 5.1618635 | G4: =G5-C2 -> #REF! | H4: =C4-H5 -> 0.14620192
G5: 0.25375693 | H5: 5.0156615
B6: Sr. No. | C6: Parameters | D6: Base | E6: UOM | F6: Changes | G6: Change in IRR | H6: Change in payback
B7: 1 | C7: Change in D:E | D7: 0:1 | F7: 3:1 | G7: - 9.51% | H7: +4.17 years
B8: 2 | C8: Change in rental cost | D8: 0.6 | E8: Rs./Pallet/day | F8: +/- 0.10 | G8: +/- 6.30% | H8: -/+ 0.26 years
B9: 3 | C9: Change in storage duration | D9: 5 | E9: days | F9: + 1 day | G9: -0.0669 | H9: +2.12 years
B10: 4 | C10: Change in project execution timeline | D10: 14 | E10: months | F10: + 1 month | G10: - 0.37% | H10: 0.00 years
B11: 5 | C11: Change in project life | D11: 15 | E11: years | F11: -/+ 5 years | G11: -/+ 1.50% | H11: +/- 0.04 years
B12: 6 | C12: Change in markup | D12: 0.15 | E12: % | F12: +/- 1% | G12: -/+ 1.91% | H12: + 1.41 / - 0.99 years
C22: Expense Parameter | D22: Annual Cost (Rs. Cr.)
C23: Lease Rent | D23: 2.24
C24: Security Deposit | D24: 0.56
C25: Total Lease Cost | D25: 2.8
C26: Electricity | D26: 0.03
C27: Manpower | D27: 0.27
C28: IT Costs | D28: 0.02
C29: Machinery & Equipment | D29: 0.55
C30: Total Operational Cost | D30: 3.67

Sheet Computations
B2: Operational Years
B3: Year | C3: 1 | D3: =IFERROR(IF(C3+1<=Inputs!$D$4,C3+1,"-"),"-") -> 2 | E3: =IFERROR(IF(D3+1<=Inputs!$D$4,D3+1,"-"),"-") -> 3 | F3: =IFERROR(IF(E3+1<=Inputs!$D$4,E3+1,"-"),"-") -> 4 | G3: =IFERROR(IF(F3+1<=Inputs!$D$4,F3+1,"-"),"-") -> 5 | H3: =IFERROR(IF(G3+1<=Inputs!$D$4,G3+1,"-"),"-") -> 6 | I3: =IFERROR(IF(H3+1<=Inputs!$D$4,H3+1,"-"),"-") -> 7 | J3: =IFERROR(IF(I3+1<=Inputs!$D$4,I3+1,"-"),"-") -> 8 | K3: =IFERROR(IF(J3+1<=Inputs!$D$4,J3+1,"-"),"-") -> 9 | ... AG3: =IFERROR(IF(AF3+1<=Inputs!$D$4,AF3+1,"-"),"-") -> -
B4: Start month | C4: =Inputs!G5+1 -> 45992 | D4: =IFERROR(C5+1,"-") -> 46357 | E4: =IFERROR(D5+1,"-") -> 46722 | F4: =IFERROR(E5+1,"-") -> 47088 | G4: =IFERROR(F5+1,"-") -> 47453 | H4: =IFERROR(G5+1,"-") -> 47818 | I4: =IFERROR(H5+1,"-") -> 48183 | J4: =IFERROR(I5+1,"-") -> 48549 | K4: =IFERROR(J5+1,"-") -> 48914 | ... AG4: =IFERROR(AF5+1,"-") -> -
B5: End month | C5: =EOMONTH(C4,11) -> 46356 | D5: =IFERROR(IF(EOMONTH(D4,11)<=Inputs!$G$6,EOMONTH(D4,11),"-"),"-") -> 46721 | E5: =IFERROR(IF(EOMONTH(E4,11)<=Inputs!$G$6,EOMONTH(E4,11),"-"),"-") -> 47087 | F5: =IFERROR(IF(EOMONTH(F4,11)<=Inputs!$G$6,EOMONTH(F4,11),"-"),"-") -> 47452 | G5: =IFERROR(IF(EOMONTH(G4,11)<=Inputs!$G$6,EOMONTH(G4,11),"-"),"-") -> 47817 | H5: =IFERROR(IF(EOMONTH(H4,11)<=Inputs!$G$6,EOMONTH(H4,11),"-"),"-") -> 48182 | I5: =IFERROR(IF(EOMONTH(I4,11)<=Inputs!$G$6,EOMONTH(I4,11),"-"),"-") -> 48548 | J5: =IFERROR(IF(EOMONTH(J4,11)<=Inputs!$G$6,EOMONTH(J4,11),"-"),"-") -> 48913 | K5: =IFERROR(IF(EOMONTH(K4,11)<=Inputs!$G$6,EOMONTH(K4,11),"-"),"-") -> 49278 | ... AG5: =IFERROR(IF(EOMONTH(AG4,11)<=Inputs!$G$6,EOMONTH(AG4,11),"-"),"-") -> -
B6: Days | C6: =IFERROR(_xlfn.DAYS(C5,C4),0)+1 -> 365 | D6: =IFERROR(_xlfn.DAYS(D5,D4),0)+1 -> 365 | E6: =IFERROR(_xlfn.DAYS(E5,E4),0)+1 -> 366 | F6: =IFERROR(_xlfn.DAYS(F5,F4),0)+1 -> 365 | G6: =IFERROR(_xlfn.DAYS(G5,G4),0)+1 -> 365 | H6: =IFERROR(_xlfn.DAYS(H5,H4),0)+1 -> 365 | I6: =IFERROR(_xlfn.DAYS(I5,I4),0)+1 -> 366 | J6: =IFERROR(_xlfn.DAYS(J5,J4),0)+1 -> 365 | ... AG6: =IFERROR(_xlfn.DAYS(AG5,AG4),0)+1 -> 1
A7: =C6*C9 -> 3258720
A8: =A7*A11 -> 2.210309e+08 | B8: Revenue
B9: # of pallet positions | C9: ='Project Cost Details'!$C$4 -> 8928 | D9: ='Project Cost Details'!$C$4 -> 8928 | E9: ='Project Cost Details'!$C$4 -> 8928 | F9: ='Project Cost Details'!$C$4 -> 8928 | G9: ='Project Cost Details'!$C$4 -> 8928 | H9: ='Project Cost Details'!$C$4 -> 8928 | I9: ='Project Cost Details'!$C$4 -> 8928 | J9: ='Project Cost Details'!$C$4 -> 8928 | ... AG9: ='Project Cost Details'!$C$4 -> 8928
B10: Utilisation | C10: =Inputs!H40 -> 0.83990912 | D10: =C10 -> 0.83990912 | E10: =D10 -> 0.83990912 | F10: =E10 -> 0.83990912 | G10: =F10 -> 0.83990912 | H10: =G10 -> 0.83990912 | I10: =H10 -> 0.83990912 | J10: =I10 -> 0.83990912 | K10: =J10 -> 0.83990912 | ... AG10: =AF10 -> 0.83990912
A11: =Inputs!D10 -> 67.827523 | B11: cost per pallet (Rs./pallet/day) | C11: =A11 -> 67.827523 | D11: =IFERROR(IF(MOD(D3-1,Inputs!$D$12)=0,Inputs!$D$10,C11*(1+D12)),0) -> 71.218899 | E11: =IFERROR(IF(MOD(E3-1,Inputs!$D$12)=0,Inputs!$D$10,D11*(1+E12)),0) -> 74.779844 | F11: =IFERROR(IF(MOD(F3-1,Inputs!$D$12)=0,Inputs!$D$10,E11*(1+F12)),0) -> 78.518836 | G11: =IFERROR(IF(MOD(G3-1,Inputs!$D$12)=0,Inputs!$D$10,F11*(1+G12)),0) -> 82.444778 | H11: =IFERROR(IF(MOD(H3-1,Inputs!$D$12)=0,Inputs!$D$10,G11*(1+H12)),0) -> 86.567017 | I11: =IFERROR(IF(MOD(I3-1,Inputs!$D$12)=0,Inputs!$D$10,H11*(1+I12)),0) -> 90.895367 | J11: =IFERROR(IF(MOD(J3-1,Inputs!$D$12)=0,Inputs!$D$10,I11*(1+J12)),0) -> 67.827523 | K11: =IFERROR(IF(MOD(K3-1,Inputs!$D$12)=0,Inputs!$D$10,J11*(1+K12)),0) -> 71.218899 | ... AG11: =IFERROR(IF(MOD(AG3-1,Inputs!$D$12)=0,Inputs!$D$10,AF11*(1+AG12)),0) -> 0
B12: escalation | C12: 0 | D12: =Inputs!$D$11 -> 0.05 | E12: =D12 -> 0.05 | F12: =E12 -> 0.05 | G12: =F12 -> 0.05 | H12: =G12 -> 0.05 | I12: =H12 -> 0.05 | J12: =I12 -> 0.05 | K12: =J12 -> 0.05 | L12: =K12 -> 0.05 | ... AG12: =AF12 -> 0.05
B13: Opportunity Cost | C13: ='Opportunity Cost'!D52 -> 14.425467 | D13: ='Opportunity Cost'!E52 -> 13.165102 | E13: ='Opportunity Cost'!F52 -> 13.629605 | F13: ='Opportunity Cost'!G52 -> 13.281556 | G13: ='Opportunity Cost'!H52 -> 13.745013 | H13: ='Opportunity Cost'!I52 -> 14.228053 | I13: ='Opportunity Cost'!J52 -> 13.899155 | J13: ='Opportunity Cost'!K52 -> 14.382397 | ... AG13: ='Opportunity Cost'!AH52 -> 0
B14: Total (rs.Cr.) | C14: =C9*C6*C11/10^7*C10+C13 -> 32.990054 | D14: =D9*D6*D11/10^7*D10+D13 -> 32.657919 | E14: =E9*E6*E11/10^7*E10+E13 -> 34.153138 | F14: =F9*F6*F11/10^7*F10+F13 -> 34.772386 | G14: =G9*G6*G11/10^7*G10+G13 -> 36.310385 | H14: =H9*H6*H11/10^7*H10+H13 -> 37.921694 | I14: =I9*I6*I11/10^7*I10+I13 -> 38.845637 | J14: =J9*J6*J11/10^7*J10+J13 -> 32.946984 | ... AG14: =AG9*AG6*AG11/10^7*AG10+AG13 -> 0
B16: Expenses
B17: ='Project Expenses'!B5 -> Operational and maintenance | C17: ='Project Expenses'!F6 -> 1.8054 | D17: ='Project Expenses'!G6 -> 1.89567 | E17: ='Project Expenses'!H6 -> 1.9904535 | F17: ='Project Expenses'!I6 -> 2.0899762 | G17: ='Project Expenses'!J6 -> 2.194475 | H17: ='Project Expenses'!K6 -> 2.3041987 | I17: ='Project Expenses'!L6 -> 2.4194087 | J17: ='Project Expenses'!M6 -> 2.5403791 | ... Q17: ='Project Expenses'!T6 -> 3.5745685
B18: ='Project Expenses'!B9 -> Manpower | C18: ='Project Expenses'!F16 -> 0.5208 | D18: ='Project Expenses'!G16 -> 0.54684 | E18: ='Project Expenses'!H16 -> 0.574182 | F18: ='Project Expenses'!I16 -> 0.6028911 | G18: ='Project Expenses'!J16 -> 0.63303566 | H18: ='Project Expenses'!K16 -> 0.66468744 | I18: ='Project Expenses'!L16 -> 0.69792181 | J18: ='Project Expenses'!M16 -> 0.7328179 | ... Q18: ='Project Expenses'!T16 -> 1.0311484
B19: ='Project Expenses'!B19 -> Power | C19: ='Project Expenses'!F25 -> 2.502066 | D19: ='Project Expenses'!G25 -> 2.502066 | E19: ='Project Expenses'!H25 -> 2.502066 | F19: ='Project Expenses'!I25 -> 2.502066 | G19: ='Project Expenses'!J25 -> 2.502066 | H19: ='Project Expenses'!K25 -> 2.502066 | I19: ='Project Expenses'!L25 -> 2.502066 | J19: ='Project Expenses'!M25 -> 2.502066 | ... Q19: ='Project Expenses'!T25 -> 2.502066
B20: ='Project Expenses'!B27 -> Water | C20: ='Project Expenses'!F29 -> 0.0657 | D20: ='Project Expenses'!G29 -> 0.0657 | E20: ='Project Expenses'!H29 -> 0.0657 | F20: ='Project Expenses'!I29 -> 0.0657 | G20: ='Project Expenses'!J29 -> 0.0657 | H20: ='Project Expenses'!K29 -> 0.0657 | I20: ='Project Expenses'!L29 -> 0.0657 | J20: ='Project Expenses'!M29 -> 0.0657 | ... Q20: ='Project Expenses'!T29 -> 0.0657
B21: ='Project Expenses'!B31 -> Repayment of Security Deposit | C21: ='Project Expenses'!F33 -> 0 | D21: ='Project Expenses'!G33 -> 0 | E21: ='Project Expenses'!H33 -> 0 | F21: ='Project Expenses'!I33 -> 0 | G21: ='Project Expenses'!J33 -> 0 | H21: ='Project Expenses'!K33 -> 0 | I21: ='Project Expenses'!L33 -> 0 | J21: ='Project Expenses'!M33 -> 8.236746 | ... AG21: ='Project Expenses'!AJ33 -> 0
B22: Land lease rentals | C22: ='Project Expenses'!F40/10^7 -> 5.961504 | D22: ='Project Expenses'!G40/10^7 -> 4.7692032 | E22: ='Project Expenses'!H40/10^7 -> 5.0076633 | F22: ='Project Expenses'!I40/10^7 -> 5.2580465 | G22: ='Project Expenses'!J40/10^7 -> 5.5209488 | H22: ='Project Expenses'!K40/10^7 -> 5.7969963 | I22: ='Project Expenses'!L40/10^7 -> 3.5769024 | J22: ='Project Expenses'!M40/10^7 -> 5.961504 | ... AG22: ='Project Expenses'!AJ40/10^7 -> 0
B23: Transportation cost | C23: ='Project Expenses'!F44/10^7 -> 0 | D23: ='Project Expenses'!G44/10^7 -> 0 | E23: ='Project Expenses'!H44/10^7 -> 0 | F23: ='Project Expenses'!I44/10^7 -> 0 | G23: ='Project Expenses'!J44/10^7 -> 0 | H23: ='Project Expenses'!K44/10^7 -> 0 | I23: ='Project Expenses'!L44/10^7 -> 0 | J23: ='Project Expenses'!M44/10^7 -> 0 | ... AG23: ='Project Expenses'!AJ44/10^7 -> 0
B24: Total | C24: =SUM(C17:C23) -> 10.85547 | D24: =SUM(D17:D23) -> 9.7794792 | E24: =SUM(E17:E23) -> 10.140065 | F24: =SUM(F17:F23) -> 10.51868 | G24: =SUM(G17:G23) -> 10.916225 | H24: =SUM(H17:H23) -> 11.333648 | I24: =SUM(I17:I23) -> 9.2619989 | J24: =SUM(J17:J23) -> 20.039213 | ... AG24: =SUM(AG17:AG23) -> 0
B26: PBIDT | C26: =C14-C24 -> 22.134584 | D26: =D14-D24 -> 22.878439 | E26: =E14-E24 -> 24.013073 | F26: =F14-F24 -> 24.253707 | G26: =G14-G24 -> 25.394159 | H26: =H14-H24 -> 26.588045 | I26: =I14-I24 -> 29.583638 | J26: =J14-J24 -> 12.907771 | ... AG26: =AG14-AG24 -> 0
B27: ROCE | C27: =C26/'Project Capex'!$D$69 -> 0.40864317 | D27: =D26/'Project Capex'!$D$69 -> 0.42237604 | E27: =E26/'Project Capex'!$D$69 -> 0.44332336 | F27: =F26/'Project Capex'!$D$69 -> 0.44776588 | G27: =G26/'Project Capex'!$D$69 -> 0.46882064 | H27: =H26/'Project Capex'!$D$69 -> 0.49086186 | I27: =I26/'Project Capex'!$D$69 -> 0.54616575 | J27: =J26/'Project Capex'!$D$69 -> 0.23830005 | ... Q27: =Q26/'Project Capex'!$D$69 -> 0.2417359
B28: Interest | C28: ='Term Loan'!D62 -> 5.1314804 | D28: ='Term Loan'!E62 -> 4.7884288 | E28: ='Term Loan'!F62 -> 4.4453772 | F28: ='Term Loan'!G62 -> 4.1023255 | G28: ='Term Loan'!H62 -> 3.7592739 | H28: ='Term Loan'!I62 -> 3.4162223 | I28: ='Term Loan'!J62 -> 3.0731707 | J28: ='Term Loan'!K62 -> 2.7301191 | ... AG28: ='Term Loan'!AH62 -> 0
B30: PBDT | C30: =C26-C28 -> 17.003103 | D30: =D26-D28 -> 18.090011 | E30: =E26-E28 -> 19.567696 | F30: =F26-F28 -> 20.151381 | G30: =G26-G28 -> 21.634885 | H30: =H26-H28 -> 23.171823 | I30: =I26-I28 -> 26.510468 | J30: =J26-J28 -> 10.177652 | ... AG30: =AG26-AG28 -> 0
B32: Depreciation | C32: ='Project Expenses'!F113 -> 6.8610323 | D32: ='Project Expenses'!G113 -> 6.8610323 | E32: ='Project Expenses'!H113 -> 6.8610323 | F32: ='Project Expenses'!I113 -> 6.8610323 | G32: ='Project Expenses'!J113 -> 6.8610323 | H32: ='Project Expenses'!K113 -> 6.8610323 | I32: ='Project Expenses'!L113 -> 6.8610323 | J32: ='Project Expenses'!M113 -> 3.4305161 | ... AG32: ='Project Expenses'!AJ113 -> 0
A34: =AVERAGE(C34:Q34) -> 17.580431 | B34: PBT | C34: =C30-C32 -> 10.142071 | D34: =D30-D32 -> 11.228978 | E34: =E30-E32 -> 12.706663 | F34: =F30-F32 -> 13.290349 | G34: =G30-G32 -> 14.773853 | H34: =H30-H32 -> 16.310791 | I34: =I30-I32 -> 19.649435 | J34: =J30-J32 -> 6.7471358 | ... AG34: =AG30-AG32 -> 0
A35: =Inputs!J5 -> 0.25168 | B35: Tax | C35: =IF(C34<0,0,$A$35*C34) -> 2.5525565 | D35: =IF(D34<0,0,$A$35*D34) -> 2.8261093 | E35: =IF(E34<0,0,$A$35*E34) -> 3.198013 | F35: =IF(F34<0,0,$A$35*F34) -> 3.344915 | G35: =IF(G34<0,0,$A$35*G34) -> 3.7182834 | H35: =IF(H34<0,0,$A$35*H34) -> 4.1050998 | I35: =IF(I34<0,0,$A$35*I34) -> 4.9453699 | J35: =IF(J34<0,0,$A$35*J34) -> 1.6981191 | ... AG35: =IF(AG34<0,0,$A$35*AG34) -> 0
B36: Deferred Tax | C36: =C46 -> -0.30915131 | D36: =D46 -> -0.0037609264 | E36: =E46 -> 0.2558209 | F36: =F46 -> 0.47646546 | G36: =G46 -> 0.66401333 | H36: =H46 -> 0.82342902 | I36: =I46 -> 0.95893236 | J36: =J46 -> 0.21071789 | ... AG36: =AG46 -> 0
A37: =AVERAGE(C37:Q37) -> 13.360886 | B37: PAT | C37: =C34-C35+C36 -> 7.2803634 | D37: =D34-D35+D36 -> 8.3991081 | E37: =E34-E35+E36 -> 9.7644711 | F37: =F34-F35+F36 -> 10.421899 | G37: =G34-G35+G36 -> 11.719583 | H37: =H34-H35+H36 -> 13.02912 | I37: =I34-I35+I36 -> 15.662998 | J37: =J34-J35+J36 -> 5.2597345 | ... AG37: =AG34-AG35+AG36 -> 0
C38: =C37/C14 -> 0.22068359 | D38: =D37/D14 -> 0.25718443 | E38: =E37/E14 -> 0.28590261 | F38: =F37/F14 -> 0.29971769 | G38: =G37/G14 -> 0.32276119 | H38: =H37/H14 -> 0.34357959 | I38: =I37/I14 -> 0.40321125 | J38: =J37/J14 -> 0.15964237 | ... AG38: =AG37/AG14 -> #DIV/0!
B39: TAXable Income
B40: PBT | C40: =C34 -> 10.142071 | D40: =D34 -> 11.228978 | E40: =E34 -> 12.706663 | F40: =F34 -> 13.290349 | G40: =G34 -> 14.773853 | H40: =H34 -> 16.310791 | I40: =I34 -> 19.649435 | J40: =J34 -> 6.7471358 | ... AG40: =AG34 -> 0
B41: Add: depreciation | C41: =C32 -> 6.8610323 | D41: =D32 -> 6.8610323 | E41: =E32 -> 6.8610323 | F41: =F32 -> 6.8610323 | G41: =G32 -> 6.8610323 | H41: =H32 -> 6.8610323 | I41: =I32 -> 6.8610323 | J41: =J32 -> 3.4305161 | ... AG41: =AG32 -> 0
B42: Subtotal | C42: =C40+C41 -> 17.003103 | D42: =D40+D41 -> 18.090011 | E42: =E40+E41 -> 19.567696 | F42: =F40+F41 -> 20.151381 | G42: =G40+G41 -> 21.634885 | H42: =H40+H41 -> 23.171823 | I42: =I40+I41 -> 26.510468 | J42: =J40+J41 -> 10.177652 | ... AG42: =AG40+AG41 -> 0
B43: Less: IT Depreciation WDV | C43: ='Project Expenses'!F236 -> 8.089383 | D43: ='Project Expenses'!G236 -> 6.8759756 | E43: ='Project Expenses'!H236 -> 5.8445792 | F43: ='Project Expenses'!I236 -> 4.9678923 | G43: ='Project Expenses'!J236 -> 4.2227085 | H43: ='Project Expenses'!K236 -> 3.5893022 | I43: ='Project Expenses'!L236 -> 3.0509069 | J43: ='Project Expenses'!M236 -> 2.5932709 | ... AG43: ='Project Expenses'!AJ236 -> 0
B44: PBT - For Income Tax | C44: =C42-C43 -> 8.9137205 | D44: =D42-D43 -> 11.214035 | E44: =E42-E43 -> 13.723116 | F44: =F42-F43 -> 15.183489 | G44: =G42-G43 -> 17.412177 | H44: =H42-H43 -> 19.582521 | I44: =I42-I43 -> 23.459561 | J44: =J42-J43 -> 7.5843811 | ... AG44: =AG42-AG43 -> 0
A45: =A35 -> 0.25168 | B45: Provision of Tax | C45: =IF(C37<0,0,$A$45*C44) -> 2.2434052 | D45: =IF(D37<0,0,$A$45*D44) -> 2.8223483 | E45: =IF(E37<0,0,$A$45*E44) -> 3.4538339 | F45: =IF(F37<0,0,$A$45*F44) -> 3.8213804 | G45: =IF(G37<0,0,$A$45*G44) -> 4.3822967 | H45: =IF(H37<0,0,$A$45*H44) -> 4.9285288 | I45: =IF(I37<0,0,$A$45*I44) -> 5.9043022 | J45: =IF(J37<0,0,$A$45*J44) -> 1.908837 | ... AG45: =IF(AG37<0,0,$A$45*AG44) -> 0
B46: Deferred Tax | C46: =(C59+C55) -> -0.30915131 | D46: =(D59+D55) -> -0.0037609264 | E46: =(E59+E55) -> 0.2558209 | F46: =(F59+F55) -> 0.47646546 | G46: =(G59+G55) -> 0.66401333 | H46: =(H59+H55) -> 0.82342902 | I46: =(I59+I55) -> 0.95893236 | J46: =(J59+J55) -> 0.21071789 | ... AG46: =(AG59+AG55) -> 0
...

Sheet Opportunity Cost
B2: Year | C2: UOM | D2: 1 | E2: =IFERROR(IF(D2<Inputs!$D$4,MIN(D2+1,Inputs!$D$4),"-"),"-") -> 2 | F2: =IFERROR(IF(E2<Inputs!$D$4,MIN(E2+1,Inputs!$D$4),"-"),"-") -> 3 | G2: =IFERROR(IF(F2<Inputs!$D$4,MIN(F2+1,Inputs!$D$4),"-"),"-") -> 4 | H2: =IFERROR(IF(G2<Inputs!$D$4,MIN(G2+1,Inputs!$D$4),"-"),"-") -> 5 | I2: =IFERROR(IF(H2<Inputs!$D$4,MIN(H2+1,Inputs!$D$4),"-"),"-") -> 6 | J2: =IFERROR(IF(I2<Inputs!$D$4,MIN(I2+1,Inputs!$D$4),"-"),"-") -> 7 | K2: =IFERROR(IF(J2<Inputs!$D$4,MIN(J2+1,Inputs!$D$4),"-"),"-") -> 8 | L2: =IFERROR(IF(K2<Inputs!$D$4,MIN(K2+1,Inputs!$D$4),"-"),"-") -> 9 | ... Y2: =IFERROR(IF(X2<Inputs!$D$4,MIN(X2+1,Inputs!$D$4),"-"),"-") -> -
A3: 1 | B3: Rental Cost
B4: Total space required to store 8928 pallets | C4: Sq. ft | D4: =8928*(36)/2/Computations!$C$10 -> 191334.99 | E4: =D4 -> 191334.99 | F4: =E4 -> 191334.99 | G4: =F4 -> 191334.99 | H4: =G4 -> 191334.99 | I4: =H4 -> 191334.99 | J4: =I4 -> 191334.99 | K4: =J4 -> 191334.99 | L4: =K4 -> 191334.99 | ... Y4: =X4 -> 191334.99
B5: Lease rental of the land | C5: Rs./sq.ft. | D5: 23 | E5: =D5*(1+E6) -> 24.15 | F5: =E5*(1+F6) -> 25.3575 | G5: =D5 -> 23 | H5: =G5*(1+H6) -> 24.15 | I5: =H5*(1+I6) -> 25.3575 | J5: =G5 -> 23 | K5: =J5*(1+K6) -> 24.15 | L5: =K5*(1+L6) -> 25.3575 | M5: =G5 -> 23 | N5: =M5*(1+N6) -> 24.15 | O5: =N5*(1+O6) -> 25.3575 | P5: =M5 -> 23 | Q5: =P5*(1+Q6) -> 24.15 | R5: =Q5*(1+R6) -> 25.3575
B6: Escalation | C6: % | D6: 0 | E6: 0.05 | F6: 0.05 | G6: 0 | H6: 0.05 | I6: 0.05 | J6: 0 | K6: 0.05 | L6: 0.05 | M6: 0 | N6: 0.05 | O6: 0.05 | P6: 0 | Q6: 0.05 | R6: 0.05
B7: Security Deposit | C7: Rs. Cr. | D7: =D4*D5*3/10^7 -> 1.3202114 | R7: =-D7 -> -1.3202114
B8: Total cost per year | C8: Rs. Cr. | D8: =D4*D5*12/10^7+D7 -> 6.601057 | E8: =E4*E5*12/10^7+E7 -> 5.5448879 | F8: =F4*F5*12/10^7+F7 -> 5.8221323 | G8: =G4*G5*12/10^7+G7 -> 5.2808456 | H8: =H4*H5*12/10^7+H7 -> 5.5448879 | I8: =I4*I5*12/10^7+I7 -> 5.8221323 | J8: =J4*J5*12/10^7+J7 -> 5.2808456 | K8: =K4*K5*12/10^7+K7 -> 5.5448879 | ... R8: =R4*R5*12/10^7+R7 -> 4.5019209
A10: 2 | B10: Operational cost
A11: a. | B11: Manpower
B12: Total number of employees | D12: Monthly salary | E12: Total annual cost
B13: Security | C13: 6 | D13: 12000 | E13: =D13*C13*12 -> 864000
B14: Site incharge | C14: 1 | D14: 50000 | E14: =D14*C14*12 -> 600000
B15: Managers | C15: 3 | D15: 15000 | E15: =D15*C15*12 -> 540000
B16: Operators | C16: 12 | D16: 10000 | E16: =D16*C16*12 -> 1440000
B17: Total | E17: =SUM(E13:E16) -> 3444000
B19: Escalation | D19: 0 | E19: 0.05 | F19: 0.05 | G19: 0.05 | H19: 0.05 | I19: 0.05 | J19: 0.05 | K19: 0.05 | L19: 0.05 | M19: 0.05 | N19: 0.05 | O19: 0.05 | P19: 0.05 | Q19: 0.05 | R19: 0.05
B20: Per year cost | C20: Rs. Cr. | D20: =E17/10^7 -> 0.3444 | E20: =D20*(1+E19) -> 0.36162 | F20: =E20*(1+F19) -> 0.379701 | G20: =F20*(1+G19) -> 0.39868605 | H20: =G20*(1+H19) -> 0.41862035 | I20: =H20*(1+I19) -> 0.43955137 | J20: =I20*(1+J19) -> 0.46152894 | K20: =J20*(1+K19) -> 0.48460539 | L20: =K20*(1+L19) -> 0.50883565 | ... R20: =Q20*(1+R19) -> 0.68188844
A22: b | B22: IT infrastructure
B23: IT assets | D23: Cost per month | E23: Total annual cost
B24: Printer | C24: 1 | D24: 5000 | E24: =D24*C24*12 -> 60000
B25: Laptops | C25: 4 | D25: =100000/12 -> 8333.3333 | E25: =D25*12*C25 -> 400000
B26: Wifi | C26: 1 | D26: 1500 | E26: =D26*C26*12 -> 18000
B27: Total | E27: =SUM(E24:E26) -> 478000
B29: Escalation | D29: 0 | E29: 0 | F29: 0 | G29: 0 | H29: 0 | I29: 0 | J29: 0 | K29: 0 | L29: 0 | M29: 0 | N29: 0 | O29: 0 | P29: 0 | Q29: 0 | R29: 0
B30: Per year cost | C30: Rs. Cr. | D30: =E27/10^7 -> 0.0478 | E30: =D30*(1+E29) -> 0.0478 | F30: =E30*(1+F29) -> 0.0478 | G30: =F30*(1+G29) -> 0.0478 | H30: =G30*(1+H29) -> 0.0478 | I30: =H30*(1+I29) -> 0.0478 | J30: =I30*(1+J29) -> 0.0478 | K30: =J30*(1+K29) -> 0.0478 | L30: =K30*(1+L29) -> 0.0478 | ... R30: =Q30*(1+R29) -> 0.0478
A32: c. | B32: Machineries
B33: Rentals
B34: Rental Electrical Forklifts charges | C34: 8 | D34: 138702.5 | E34: =C34*D34*12 -> 13315440
B35: BOPT | C35: 4 | D35: 50000 | E35: =C35*D35*12 -> 2400000
B36: Total | E36: =SUM(E34:E35) -> 15715440
B37: One time payment
B38: Dock Levellers | C38: 8 | D38: =392044*1.18 -> 462611.92 | E38: =C38*D38 -> 3700895.4
B39: Installation | C39: 8 | D39: =16500*1.18 -> 19470 | E39: =C39*D39 -> 155760
B40: Total | E40: =E38+E39 -> 3856655.4
B42: Per year cost | C42: Rs. Cr. | D42: =E36/10^7+E40/10^7 -> 1.9572095 | E42: =$E$36/10^7 -> 1.571544 | F42: =$E$36/10^7 -> 1.571544 | G42: =$E$36/10^7 -> 1.571544 | H42: =$E$36/10^7 -> 1.571544 | I42: =$E$36/10^7 -> 1.571544 | J42: =$E$36/10^7 -> 1.571544 | K42: =$E$36/10^7 -> 1.571544 | L42: =$E$36/10^7 -> 1.571544 | ... R42: =$E$36/10^7 -> 1.571544
A44: d. | B44: Transporatation cost
B45: Assumption
B46: Distance from plant | C46: 20 kms
B47: Per trip cost | C47: 10000
B48: Total trips per day | C48: 15
...

Sheet Project Capex
B2: Month | E2: =Inputs!G3 -> 45566 | F2: =IFERROR(IF(EOMONTH(E2,0.5)+1<=Inputs!$G$5,EOMONTH(E2,0.5)+1,"-"),"-") -> 45597 | G2: =IFERROR(IF(EOMONTH(F2,0.5)+1<=Inputs!$G$5,EOMONTH(F2,0.5)+1,"-"),"-") -> 45627 | H2: =IFERROR(IF(EOMONTH(G2,0.5)+1<=Inputs!$G$5,EOMONTH(G2,0.5)+1,"-"),"-") -> 45658 | I2: =IFERROR(IF(EOMONTH(H2,0.5)+1<=Inputs!$G$5,EOMONTH(H2,0.5)+1,"-"),"-") -> 45689 | J2: =IFERROR(IF(EOMONTH(I2,0.5)+1<=Inputs!$G$5,EOMONTH(I2,0.5)+1,"-"),"-") -> 45717 | K2: =IFERROR(IF(EOMONTH(J2,0.5)+1<=Inputs!$G$5,EOMONTH(J2,0.5)+1,"-"),"-") -> 45748 | L2: =IFERROR(IF(EOMONTH(K2,0.5)+1<=Inputs!$G$5,EOMONTH(K2,0.5)+1,"-"),"-") -> 45778 | M2: =IFERROR(IF(EOMONTH(L2,0.5)+1<=Inputs!$G$5,EOMONTH(L2,0.5)+1,"-"),"-") -> 45809 | ... AG2: =IFERROR(IF(EOMONTH(AF2,0.5)+1<=Inputs!$G$5,EOMONTH(AF2,0.5)+1,"-"),"-") -> - | BB2: 1 | BC2: Jan | BD2: Q4
B3: Quarter | E3: =IFERROR((VLOOKUP(MONTH(E2),$BB$2:$BD$13,3,FALSE) & " " & IF(OR(MONTH(E2)=1,MONTH(E2)=2,MONTH(E2)=3),YEAR(E2),YEAR(E2)+1)),"-") -> Q3 2025 | F3: =IFERROR((VLOOKUP(MONTH(F2),$BB$2:$BD$13,3,FALSE) & " " & IF(OR(MONTH(F2)=1,MONTH(F2)=2,MONTH(F2)=3),YEAR(F2),YEAR(F2)+1)),"-") -> Q3 2025 | G3: =IFERROR((VLOOKUP(MONTH(G2),$BB$2:$BD$13,3,FALSE) & " " & IF(OR(MONTH(G2)=1,MONTH(G2)=2,MONTH(G2)=3),YEAR(G2),YEAR(G2)+1)),"-") -> Q3 2025 | H3: =IFERROR((VLOOKUP(MONTH(H2),$BB$2:$BD$13,3,FALSE) & " " & IF(OR(MONTH(H2)=1,MONTH(H2)=2,MONTH(H2)=3),YEAR(H2),YEAR(H2)+1)),"-") -> Q4 2025 | I3: =IFERROR((VLOOKUP(MONTH(I2),$BB$2:$BD$13,3,FALSE) & " " & IF(OR(MONTH(I2)=1,MONTH(I2)=2,MONTH(I2)=3),YEAR(I2),YEAR(I2)+1)),"-") -> Q4 2025 | J3: =IFERROR((VLOOKUP(MONTH(J2),$BB$2:$BD$13,3,FALSE) & " " & IF(OR(MONTH(J2)=1,MONTH(J2)=2,MONTH(J2)=3),YEAR(J2),YEAR(J2)+1)),"-") -> Q4 2025 | K3: =IFERROR((VLOOKUP(MONTH(K2),$BB$2:$BD$13,3,FALSE) & " " & IF(OR(MONTH(K2)=1,MONTH(K2)=2,MONTH(K2)=3),YEAR(K2),YEAR(K2)+1)),"-") -> Q1 2026 | L3: =IFERROR((VLOOKUP(MONTH(L2),$BB$2:$BD$13,3,FALSE) & " " & IF(OR(MONTH(L2)=1,MONTH(L2)=2,MONTH(L2)=3),YEAR(L2),YEAR(L2)+1)),"-") -> Q1 2026 | ... AG3: =IFERROR((VLOOKUP(MONTH(AG2),$BB$2:$BD$13,3,FALSE) & " " & IF(OR(MONTH(AG2)=1,MONTH(AG2)=2,MONTH(AG2)=3),YEAR(AG2),YEAR(AG2)+1)),"-") -> - | BB3: =BB2+1 -> 2 | BC3: Feb | BD3: Q4
B4: Year | E4: =IFERROR(("FY " & YEAR(E2)+1),"-") -> FY 2025 | F4: =IFERROR(("FY " & YEAR(F2)+1),"-") -> FY 2025 | G4: =IFERROR(("FY " & YEAR(G2)+1),"-") -> FY 2025 | H4: =IFERROR(("FY " & YEAR(H2)+1),"-") -> FY 2026 | I4: =IFERROR(("FY " & YEAR(I2)+1),"-") -> FY 2026 | J4: =IFERROR(("FY " & YEAR(J2)+1),"-") -> FY 2026 | K4: =IFERROR(("FY " & YEAR(K2)+1),"-") -> FY 2026 | L4: =IFERROR(("FY " & YEAR(L2)+1),"-") -> FY 2026 | ... AG4: =IFERROR(("FY " & YEAR(AG2)+1),"-") -> - | BB4: =BB3+1 -> 3 | BC4: Mar | BD4: Q4
BB5: =BB4+1 -> 4 | BC5: Apr | BD5: Q1
B6: CAPEX | C6: 0.038135593 | BB6: =BB5+1 -> 5 | BC6: May | BD6: Q1
B7: ='Project Cost Details'!B3 -> ASRS | C7: =(1-E8-50%)/2 -> 0.038135593 | BB7: =BB6+1 -> 6 | BC7: Jun | BD7: Q1
B8: ='Project Cost Details'!B4 -> Racking system | C8: =1-E8-L8-M8 -> 0.40423729 | D8: =SUM(E8:AG8) -> 1 | E8: 0.42372881 | J8: 0 | K8: 0 | L8: 0.073728814 | M8: 0.098305085 | N8: 0.14745763 | O8: 0.12288136 | P8: 0.049152542 | Q8: =5%/1.18 -> 0.042372881 | R8: =5%/1.18 -> 0.042372881 | AP8: =AQ8/$AQ$38 -> 0.42372881 | AQ8: 153000000 | AR8: Received | BB8: =BB7+1 -> 7 | BC8: Jul | BD8: Q2
B9: ='Project Cost Details'!B5 -> Cladding for high bay | D9: =SUM(E9:AG9) -> 1 | E9: 0.42372881 | J9: 0 | K9: 0 | L9: 0.073728814 | M9: 0.098305085 | N9: 0.14745763 | O9: 0.12288136 | P9: 0.049152542 | Q9: =5%/1.18 -> 0.042372881 | R9: =5%/1.18 -> 0.042372881 | AP9: =AQ9/$AQ$38 -> 0.073728814 | AQ9: 26622000 | AR9: 45778 | BB9: =BB8+1 -> 8 | BC9: Aug | BD9: Q2
B10: ='Project Cost Details'!B6 -> Double deep Stacker crane | D10: =SUM(E10:AG10) -> 1 | E10: 0.42372881 | J10: 0 | K10: 0 | L10: 0.073728814 | M10: 0.098305085 | N10: 0.14745763 | O10: 0.12288136 | P10: 0.049152542 | Q10: =5%/1.18 -> 0.042372881 | R10: =5%/1.18 -> 0.042372881 | AP10: =AQ10/$AQ$38 -> 0.098305085 | AQ10: 35496000 | AR10: 45809 | BB10: =BB9+1 -> 9 | BC10: Sep | BD10: Q2
B11: ='Project Cost Details'!B7 -> Bottom Rail with aisle accessories | D11: =SUM(E11:AG11) -> 1 | E11: 0.42372881 | J11: 0 | K11: 0 | L11: 0.073728814 | M11: 0.098305085 | N11: 0.14745763 | O11: 0.12288136 | P11: 0.049152542 | Q11: =5%/1.18 -> 0.042372881 | R11: =5%/1.18 -> 0.042372881 | AP11: =AQ11/$AQ$38 -> 0 | BB11: =BB10+1 -> 10 | BC11: Oct | BD11: Q3
B12: ='Project Cost Details'!B8 -> Conveyor system | D12: =SUM(E12:AG12) -> 1 | E12: 0.42372881 | J12: 0 | K12: 0 | L12: 0.073728814 | M12: 0.098305085 | N12: 0.14745763 | O12: 0.12288136 | P12: 0.049152542 | Q12: =5%/1.18 -> 0.042372881 | R12: =5%/1.18 -> 0.042372881 | AP12: =AQ12/$AQ$38 -> 0.14745763 | AQ12: 53244000 | AR12: 45839 | BB12: =BB11+1 -> 11 | BC12: Nov | BD12: Q3
B13: ='Project Cost Details'!B9 -> Critical spares | D13: =SUM(E13:AG13) -> 1 | E13: 0.42372881 | J13: 0 | K13: 0 | L13: 0.073728814 | M13: 0.098305085 | N13: 0.14745763 | O13: 0.12288136 | P13: 0.049152542 | Q13: =5%/1.18 -> 0.042372881 | R13: =5%/1.18 -> 0.042372881 | AP13: =AQ13/$AQ$38 -> 0 | BB13: =BB12+1 -> 12 | BC13: Dec | BD13: Q3
B14: ='Project Cost Details'!B10 -> Metal pallets | D14: =SUM(E14:AG14) -> 1 | E14: 0.42372881 | J14: 0 | K14: 0 | L14: 0.073728814 | M14: 0.098305085 | N14: 0.14745763 | O14: 0.12288136 | P14: 0.049152542 | Q14: =5%/1.18 -> 0.042372881 | R14: =5%/1.18 -> 0.042372881 | AP14: =AQ14/$AQ$38 -> 0
B15: ='Project Cost Details'!B11 -> Discount | D15: =SUM(E15:AG15) -> 1 | E15: 0.42372881 | J15: 0 | K15: 0 | L15: 0.073728814 | M15: 0.098305085 | N15: 0.14745763 | O15: 0.12288136 | P15: 0.049152542 | Q15: =1-SUM(E15:P15) -> 0.084745763 | AP15: =AQ15/$AQ$38 -> 0.12288136 | AQ15: 44370000 | AR15: 45870
B16: ='Project Cost Details'!B12 -> Civil Cost
B17: ='Project Cost Details'!B13 -> Earthworks and soiling | D17: =SUM(E17:AG17) -> 1 | K17: =30% -> 0.3 | L17: 0.6 | M17: 0.1
B18: ='Project Cost Details'!B14 -> PCC works | D18: =SUM(E18:AG18) -> 1 | K18: =30% -> 0.3 | L18: 0.6 | M18: 0.1
B19: ='Project Cost Details'!B15 -> RCC works | D19: =SUM(E19:AG19) -> 1 | K19: =30% -> 0.3 | L19: 0.6 | M19: 0.1
B20: ='Project Cost Details'!B16 -> Shuttering | D20: =SUM(E20:AG20) -> 1 | K20: =30% -> 0.3 | L20: 0.6 | M20: 0.1
B21: ='Project Cost Details'!B17 -> TMT bards Fe 500 | D21: =SUM(E21:AG21) -> 1 | K21: =30% -> 0.3 | L21: 0.6 | M21: 0.1
B22: ='Project Cost Details'!B18 -> Masonary works | D22: =SUM(E22:AG22) -> 1 | K22: =30% -> 0.3 | L22: 0.6 | M22: 0.1
B23: ='Project Cost Details'!B19 -> Plastering | D23: =SUM(E23:AG23) -> 1 | K23: =30% -> 0.3 | L23: 0.6 | M23: 0.1
B24: ='Project Cost Details'!B20 -> VDF Flooring | D24: =SUM(E24:AG24) -> 1 | K24: =30% -> 0.3 | L24: 0.6 | M24: 0.1
B25: ='Project Cost Details'!B21 -> J BOLTS installation | D25: =SUM(E25:AG25) -> 1 | K25: =30% -> 0.3 | L25: 0.6 | M25: 0.1
B26: ='Project Cost Details'!B22 -> Baseplate Grouting | D26: =SUM(E26:AG26) -> 1 | K26: =30% -> 0.3 | L26: 0.6 | M26: 0.1
B27: ='Project Cost Details'!B23 -> Miscellenous | D27: =SUM(E27:AG27) -> 1 | K27: =30% -> 0.3 | L27: 0.6 | M27: 0.1
B28: ='Project Cost Details'!B24 -> Road | D28: =SUM(E28:AG28) -> 1 | M28: 0.1 | N28: 0.2 | O28: 0.2 | P28: 0.2 | Q28: 0.2 | R28: 0.1
B29: ='Project Cost Details'!B25 -> Electrical | D29: =SUM(E29:AG29) -> 0
B30: ='Project Cost Details'!B26 -> CDA | D30: =SUM(E30:AG30) -> 0
B31: ='Project Cost Details'!B27 -> FHS and FAS for the ASRS | D31: =SUM(E31:AG31) -> 0
B32: ='Project Cost Details'!B28 -> Dock levellers | D32: =SUM(E32:AG32) -> 1 | I32: 0.6 | J32: 0.2 | L32: 0.1 | M32: 0.1 | Q32: 0 | R32: 0 | AP32: =AQ32/$AQ$38 -> 0
B33: ='Project Cost Details'!B29 -> Contingency | D33: =SUM(E33:AG33) -> 1 | J33: 0.5 | R33: 0.5 | AP33: =AQ33/$AQ$38 -> 0
B34: ='Project Cost Details'!B30 -> Pre - operating expenses | D34: =SUM(E34:AG34) -> 1 | E34: =1/Inputs!$G$4 -> 0.071428571 | F34: =1/Inputs!$G$4 -> 0.071428571 | G34: =1/Inputs!$G$4 -> 0.071428571 | H34: =1/Inputs!$G$4 -> 0.071428571 | I34: =1/Inputs!$G$4 -> 0.071428571 | J34: =1/Inputs!$G$4 -> 0.071428571 | K34: =1/Inputs!$G$4 -> 0.071428571 | L34: =1/Inputs!$G$4 -> 0.071428571 | ... R34: =1/Inputs!$G$4 -> 0.071428571 | AP34: =AQ34/$AQ$38 -> 0.049152542 | AQ34: 17748000 | AR34: 45901
B35: ='Project Cost Details'!B31 -> IDC | D35: =SUM(E35:AG35) -> 1 | E35: =1/Inputs!$G$4 -> 0.071428571 | F35: =1/Inputs!$G$4 -> 0.071428571 | G35: =1/Inputs!$G$4 -> 0.071428571 | H35: =1/Inputs!$G$4 -> 0.071428571 | I35: =1/Inputs!$G$4 -> 0.071428571 | J35: =1/Inputs!$G$4 -> 0.071428571 | K35: =1/Inputs!$G$4 -> 0.071428571 | L35: =1/Inputs!$G$4 -> 0.071428571 | ... R35: =1/Inputs!$G$4 -> 0.071428571 | AP35: =AQ35/$AQ$38 -> 0
B36: ='Project Cost Details'!B32 -> Finance cost | D36: =SUM(E36:AG36) -> 1 | E36: =1/Inputs!$G$4 -> 0.071428571 | F36: =1/Inputs!$G$4 -> 0.071428571 | G36: =1/Inputs!$G$4 -> 0.071428571 | H36: =1/Inputs!$G$4 -> 0.071428571 | I36: =1/Inputs!$G$4 -> 0.071428571 | J36: =1/Inputs!$G$4 -> 0.071428571 | K36: =1/Inputs!$G$4 -> 0.071428571 | L36: =1/Inputs!$G$4 -> 0.071428571 | ... R36: =1/Inputs!$G$4 -> 0.071428571 | AP36: =AQ36/$AQ$38 -> 0.042372881 | AQ36: 15300000 | AR36: 45931
B37: Total | AP37: =AQ37/$AQ$38 -> 0.042372881 | AQ37: 15300000 | AR37: 45962
AP38: =SUM(AP8:AP37) -> 1 | AQ38: =SUM(AQ8:AQ37) -> 361080000
B39: =B7 -> ASRS | E39: =SUM(E40:E47) -> 15.3 | F39: =SUM(F40:F47) -> 0 | G39: =SUM(G40:G47) -> 0 | H39: =SUM(H40:H47) -> 0 | I39: =SUM(I40:I47) -> 0 | J39: =SUM(J40:J47) -> 0 | K39: =SUM(K40:K47) -> 0 | L39: =SUM(L40:L47) -> 2.6622 | ... R39: =SUM(R40:R47) -> 1.5313838
B40: =B8 -> Racking system | C40: ='Project Cost Details'!G4/10^7 -> 15.04193 | D40: =SUM(E40:AG40) -> 15.04193 | E40: =$C40*E8 -> 6.3736992 | F40: =$C40*F8 -> 0 | G40: =$C40*G8 -> 0 | H40: =$C40*H8 -> 0 | I40: =$C40*I8 -> 0 | J40: =$C40*J8 -> 0 | K40: =$C40*K8 -> 0 | L40: =$C40*L8 -> 1.1090237 | ... AG40: =$C40*AG8 -> 0
B41: =B9 -> Cladding for high bay | C41: ='Project Cost Details'!G5/10^7 -> 1.416 | D41: =SUM(E41:AG41) -> 1.416 | E41: =$C41*E9 -> 0.6 | F41: =$C41*F9 -> 0 | G41: =$C41*G9 -> 0 | H41: =$C41*H9 -> 0 | I41: =$C41*I9 -> 0 | J41: =$C41*J9 -> 0 | K41: =$C41*K9 -> 0 | L41: =$C41*L9 -> 0.1044 | ... AG41: =$C41*AG9 -> 0
...

Sheet Term Loan
B2: Project Details | F2: Month | G2: Qtr | I2: Year | J2: 0 | K2: 1 | L2: 2 | M2: =L2+1 -> 3 | N2: =M2+1 -> 4 | O2: =N2+1 -> 5 | P2: =O2+1 -> 6 | Q2: =P2+1 -> 7 | R2: =Q2+1 -> 8 | S2: =R2+1 -> 9 | T2: =S2+1 -> 10 | ... AF2: =AE2+1 -> 22
B3: Total project cost | C3: ='Project Capex'!D69 -> 54.166044 | D3: Crore | F3: 1 | G3: Q4 | I3: Interest Rate | J3: 0.095 | K3: 0.095 | L3: 0.095 | M3: 0.095 | N3: 0.095 | O3: 0.095 | P3: 0.095 | Q3: 0.095 | R3: 0.095 | S3: 0.095 | T3: 0.095 | U3: 0.095 | V3: 0.095 | W3: 0.095 | X3: 0.095 | Y3: 0.095 | Z3: 0.095 | AA3: 0.095 | AB3: 0.095 | AC3: 0.095 | AD3: 0.095 | AE3: 0.095 | AF3: 0.095
B4: Equity | C4: ='Project Cost Details'!G39/10^7 -> 5.4166044e-11 | D4: Crore | F4: 2 | G4: Q4
B5: Debt | C5: ='Project Cost Details'!G38/10^7 -> 54.166044 | D5: Crore | F5: 3 | G5: Q4
B6: Total period of loan | C6: =Inputs!D4 -> 15 | D6: years | F6: =F5+1 -> 4 | G6: Q1
B7: Total months | C7: =C6*12 -> 180 | D7: month | F7: =F6+1 -> 5 | G7: Q1
B8: Total quarter | C8: =C6*4 -> 60 | D8: quarter | F8: =F7+1 -> 6 | G8: Q1
F9: =F8+1 -> 7 | G9: Q2
B10: Loan | F10: =F9+1 -> 8 | G10: Q2
B11: Total loan repayment months | C11: =C6*12-C15 -> 174 | D11: months | F11: =F10+1 -> 9 | G11: Q2
B12: Total quarter | C12: =C6*4-ROUNDDOWN(C15/3,0) -> 58 | D12: quarter | F12: =F11+1 -> 10 | G12: Q3
B13: Interest | C13: 0 | D13: Crore | F13: =F12+1 -> 11 | G13: Q3
B14: IDC | C14: =A31 -> 3.4026072 | D14: Crore | F14: =F13+1 -> 12 | G14: Q3
B15: Moratorium period | C15: 6 | D15: months
B16: Type of payment | C16: Annually
B19: Type | C19: =IF(C20<=Inputs!$G$5,"Cons","Beyond Cons") -> Cons | D19: =IF(D20<=Inputs!$G$5,"Cons","Beyond Cons") -> Cons | E19: =IF(E20<=Inputs!$G$5,"Cons","Beyond Cons") -> Cons | F19: =IF(F20<=Inputs!$G$5,"Cons","Beyond Cons") -> Cons | G19: =IF(G20<=Inputs!$G$5,"Cons","Beyond Cons") -> Cons | H19: =IF(H20<=Inputs!$G$5,"Cons","Beyond Cons") -> Cons | I19: =IF(I20<=Inputs!$G$5,"Cons","Beyond Cons") -> Cons | J19: =IF(J20<=Inputs!$G$5,"Cons","Beyond Cons") -> Cons | ... IC19: =IF(IC20<=Inputs!$G$5,"Cons","Beyond Cons") -> Beyond Cons
B20: Month | C20: =Inputs!G3 -> 45566 | D20: =IFERROR(IF(EOMONTH(C20,0.5)+1<=EOMONTH(Inputs!$G$5,$C$7),EOMONTH(C20,0.5)+1,"-"),"-") -> 45597 | E20: =IFERROR(IF(EOMONTH(D20,0.5)+1<=EOMONTH(Inputs!$G$5,$C$7),EOMONTH(D20,0.5)+1,"-"),"-") -> 45627 | F20: =IFERROR(IF(EOMONTH(E20,0.5)+1<=EOMONTH(Inputs!$G$5,$C$7),EOMONTH(E20,0.5)+1,"-"),"-") -> 45658 | G20: =IFERROR(IF(EOMONTH(F20,0.5)+1<=EOMONTH(Inputs!$G$5,$C$7),EOMONTH(F20,0.5)+1,"-"),"-") -> 45689 | H20: =IFERROR(IF(EOMONTH(G20,0.5)+1<=EOMONTH(Inputs!$G$5,$C$7),EOMONTH(G20,0.5)+1,"-"),"-") -> 45717 | I20: =IFERROR(IF(EOMONTH(H20,0.5)+1<=EOMONTH(Inputs!$G$5,$C$7),EOMONTH(H20,0.5)+1,"-"),"-") -> 45748 | J20: =IFERROR(IF(EOMONTH(I20,0.5)+1<=EOMONTH(Inputs!$G$5,$C$7),EOMONTH(I20,0.5)+1,"-"),"-") -> 45778 | K20: =IFERROR(IF(EOMONTH(J20,0.5)+1<=EOMONTH(Inputs!$G$5,$C$7),EOMONTH(J20,0.5)+1,"-"),"-") -> 45809 | ... IC20: =IFERROR(IF(EOMONTH(IB20,0.5)+1<=EOMONTH(Inputs!$G$5,$C$7),EOMONTH(IB20,0.5)+1,"-"),"-") -> -
B21: Quarter | C21: =IFERROR((VLOOKUP(MONTH(C20),$F$3:$G$14,2,FALSE) & " " & IF(OR(MONTH(C20)=1,MONTH(C20)=2,MONTH(C20)=3),YEAR(C20),YEAR(C20)+1)),"-") -> Q3 2025 | D21: =IFERROR((VLOOKUP(MONTH(D20),$F$3:$G$14,2,FALSE) & " " & IF(OR(MONTH(D20)=1,MONTH(D20)=2,MONTH(D20)=3),YEAR(D20),YEAR(D20)+1)),"-") -> Q3 2025 | E21: =IFERROR((VLOOKUP(MONTH(E20),$F$3:$G$14,2,FALSE) & " " & IF(OR(MONTH(E20)=1,MONTH(E20)=2,MONTH(E20)=3),YEAR(E20),YEAR(E20)+1)),"-") -> Q3 2025 | F21: =IFERROR((VLOOKUP(MONTH(F20),$F$3:$G$14,2,FALSE) & " " & IF(OR(MONTH(F20)=1,MONTH(F20)=2,MONTH(F20)=3),YEAR(F20),YEAR(F20)+1)),"-") -> Q4 2025 | G21: =IFERROR((VLOOKUP(MONTH(G20),$F$3:$G$14,2,FALSE) & " " & IF(OR(MONTH(G20)=1,MONTH(G20)=2,MONTH(G20)=3),YEAR(G20),YEAR(G20)+1)),"-") -> Q4 2025 | H21: =IFERROR((VLOOKUP(MONTH(H20),$F$3:$G$14,2,FALSE) & " " & IF(OR(MONTH(H20)=1,MONTH(H20)=2,MONTH(H20)=3),YEAR(H20),YEAR(H20)+1)),"-") -> Q4 2025 | I21: =IFERROR((VLOOKUP(MONTH(I20),$F$3:$G$14,2,FALSE) & " " & IF(OR(MONTH(I20)=1,MONTH(I20)=2,MONTH(I20)=3),YEAR(I20),YEAR(I20)+1)),"-") -> Q1 2026 | J21: =IFERROR((VLOOKUP(MONTH(J20),$F$3:$G$14,2,FALSE) & " " & IF(OR(MONTH(J20)=1,MONTH(J20)=2,MONTH(J20)=3),YEAR(J20),YEAR(J20)+1)),"-") -> Q1 2026 | ... IC21: =IFERROR((VLOOKUP(MONTH(IC20),$F$3:$G$14,2,FALSE) & " " & IF(OR(MONTH(IC20)=1,MONTH(IC20)=2,MONTH(IC20)=3),YEAR(IC20),YEAR(IC20)+1)),"-") -> -
B22: Year | C22: =IFERROR(("FY " & IF(OR(MONTH(C20)=1,MONTH(C20)=2,MONTH(C20)=3),YEAR(C20),YEAR(C20)+1)),"-") -> FY 2025 | D22: =IFERROR(("FY " & IF(OR(MONTH(D20)=1,MONTH(D20)=2,MONTH(D20)=3),YEAR(D20),YEAR(D20)+1)),"-") -> FY 2025 | E22: =IFERROR(("FY " & IF(OR(MONTH(E20)=1,MONTH(E20)=2,MONTH(E20)=3),YEAR(E20),YEAR(E20)+1)),"-") -> FY 2025 | F22: =IFERROR(("FY " & IF(OR(MONTH(F20)=1,MONTH(F20)=2,MONTH(F20)=3),YEAR(F20),YEAR(F20)+1)),"-") -> FY 2025 | G22: =IFERROR(("FY " & IF(OR(MONTH(G20)=1,MONTH(G20)=2,MONTH(G20)=3),YEAR(G20),YEAR(G20)+1)),"-") -> FY 2025 | H22: =IFERROR(("FY " & IF(OR(MONTH(H20)=1,MONTH(H20)=2,MONTH(H20)=3),YEAR(H20),YEAR(H20)+1)),"-") -> FY 2025 | I22: =IFERROR(("FY " & IF(OR(MONTH(I20)=1,MONTH(I20)=2,MONTH(I20)=3),YEAR(I20),YEAR(I20)+1)),"-") -> FY 2026 | J22: =IFERROR(("FY " & IF(OR(MONTH(J20)=1,MONTH(J20)=2,MONTH(J20)=3),YEAR(J20),YEAR(J20)+1)),"-") -> FY 2026 | ... IC22: =IFERROR(("FY " & IF(OR(MONTH(IC20)=1,MONTH(IC20)=2,MONTH(IC20)=3),YEAR(IC20),YEAR(IC20)+1)),"-") -> -
B23: Count | C23: =IF(C19="Cons",0,1) -> 0 | D23: =IF(D19="Cons",0,IF(D20="-",0,C23+1)) -> 0 | E23: =IF(E19="Cons",0,IF(E20="-",0,D23+1)) -> 0 | F23: =IF(F19="Cons",0,IF(F20="-",0,E23+1)) -> 0 | G23: =IF(G19="Cons",0,IF(G20="-",0,F23+1)) -> 0 | H23: =IF(H19="Cons",0,IF(H20="-",0,G23+1)) -> 0 | I23: =IF(I19="Cons",0,IF(I20="-",0,H23+1)) -> 0 | J23: =IF(J19="Cons",0,IF(J20="-",0,I23+1)) -> 0 | K23: =IF(K19="Cons",0,IF(K20="-",0,J23+1)) -> 0 | ... IC23: =IF(IC19="Cons",0,IF(IC20="-",0,IB23+1)) -> 0
B24: Qtr | C24: =IF(C23=0,0,MOD(C23,3)) -> 0 | D24: =IF(D23=0,0,ROUNDUP(D23/3,0)) -> 0 | E24: =IF(E23=0,0,ROUNDUP(E23/3,0)) -> 0 | F24: =IF(F23=0,0,ROUNDUP(F23/3,0)) -> 0 | G24: =IF(G23=0,0,ROUNDUP(G23/3,0)) -> 0 | H24: =IF(H23=0,0,ROUNDUP(H23/3,0)) -> 0 | I24: =IF(I23=0,0,ROUNDUP(I23/3,0)) -> 0 | J24: =IF(J23=0,0,ROUNDUP(J23/3,0)) -> 0 | K24: =IF(K23=0,0,ROUNDUP(K23/3,0)) -> 0 | ... IC24: =IF(IC23=0,0,ROUNDUP(IC23/3,0)) -> 0
B25: Year | C25: =IF(C23=0,0,MOD(C23,12)) -> 0 | D25: =IF(D23=0,0,ROUNDUP(D23/12,0)) -> 0 | E25: =IF(E23=0,0,ROUNDUP(E23/12,0)) -> 0 | F25: =IF(F23=0,0,ROUNDUP(F23/12,0)) -> 0 | G25: =IF(G23=0,0,ROUNDUP(G23/12,0)) -> 0 | H25: =IF(H23=0,0,ROUNDUP(H23/12,0)) -> 0 | I25: =IF(I23=0,0,ROUNDUP(I23/12,0)) -> 0 | J25: =IF(J23=0,0,ROUNDUP(J23/12,0)) -> 0 | K25: =IF(K23=0,0,ROUNDUP(K23/12,0)) -> 0 | ... IC25: =IF(IC23=0,0,ROUNDUP(IC23/12,0)) -> 0
B27: Interest Rate | C27: =HLOOKUP(C25,$J$2:$AF$3,2,FALSE)/12 -> 0.0079166667 | D27: =HLOOKUP(D25,$J$2:$AF$3,2,FALSE)/12 -> 0.0079166667 | E27: =HLOOKUP(E25,$J$2:$AF$3,2,FALSE)/12 -> 0.0079166667 | F27: =HLOOKUP(F25,$J$2:$AF$3,2,FALSE)/12 -> 0.0079166667 | G27: =HLOOKUP(G25,$J$2:$AF$3,2,FALSE)/12 -> 0.0079166667 | H27: =HLOOKUP(H25,$J$2:$AF$3,2,FALSE)/12 -> 0.0079166667 | I27: =HLOOKUP(I25,$J$2:$AF$3,2,FALSE)/12 -> 0.0079166667 | J27: =HLOOKUP(J25,$J$2:$AF$3,2,FALSE)/12 -> 0.0079166667 | ... IC27: =HLOOKUP(IC25,$J$2:$AF$3,2,FALSE)/12 -> 0.0079166667
B29: CAPEX requirement | C29: =IFERROR(_xlfn.XLOOKUP(C20,'Project Capex'!$E$2:$X$2,'Project Capex'!$E$69:$X$69),0) -> 15.600953 | D29: =IFERROR(_xlfn.XLOOKUP(D20,'Project Capex'!$E$2:$X$2,'Project Capex'!$E$69:$X$69),0) -> 0.30095298 | E29: =IFERROR(_xlfn.XLOOKUP(E20,'Project Capex'!$E$2:$X$2,'Project Capex'!$E$69:$X$69),0) -> 0.30095298 | F29: =IFERROR(_xlfn.XLOOKUP(F20,'Project Capex'!$E$2:$X$2,'Project Capex'!$E$69:$X$69),0) -> 0.30095298 | G29: =IFERROR(_xlfn.XLOOKUP(G20,'Project Capex'!$E$2:$X$2,'Project Capex'!$E$69:$X$69),0) -> 0.80403491 | H29: =IFERROR(_xlfn.XLOOKUP(H20,'Project Capex'!$E$2:$X$2,'Project Capex'!$E$69:$X$69),0) -> 1.657997 | I29: =IFERROR(_xlfn.XLOOKUP(I20,'Project Capex'!$E$2:$X$2,'Project Capex'!$E$69:$X$69),0) -> 2.9820605 | J29: =IFERROR(_xlfn.XLOOKUP(J20,'Project Capex'!$E$2:$X$2,'Project Capex'!$E$69:$X$69),0) -> 8.409215 | ... W29: =IFERROR(_xlfn.XLOOKUP(W20,'Project Capex'!$E$2:$X$2,'Project Capex'!$E$69:$X$69),0) -> 0
